<?xml version="1.0" ?>
<!-- =================================================================================== -->
<!-- |    This document was autogenerated by xacro from ../../reachy_ws/src/reachy2_core/reachy_description/urdf/reachy.urdf.xacro | -->
<!-- |    EDITING THIS FILE BY HAND IS NOT RECOMMENDED                                 | -->
<!-- =================================================================================== -->
<robot name="reachy2">
  <!-- convergence angle (rad) of the cameras. 0=parallel-->
  <!-- URDF definition is so stupid we have to do that... -->
  <!-- <material name="gripperblack"> -->
  <!--     <color rgba="0.4 0.4 0.4 1"/> -->
  <!-- </material> -->
  <!-- <material name="gripperwhite"> -->
  <!--     <color rgba="0.9 0.9 0.9 1"/> -->
  <!-- </material> -->
  <!-- <material name="reachy_yellow"> -->
  <!--     <color rgba="0.8 0.8 0.0 1"/> -->
  <!-- </material> -->
  <!-- <material name="reachy_grey"> -->
  <!--     <color rgba="0.8 0.8 0.8 1"/> -->
  <!-- </material> -->
  <!-- <material name="reachy_metal"> -->
  <!--     <color rgba="0.85 0.85 0.85 1.0"/> -->
  <!-- </material> -->
  <!-- <material name="torsoblack"> -->
  <!--     <color rgba="0.5 0.5 0.5 1.0"/> -->
  <!-- </material> -->
  <!-- <material name="eyewhite"> -->
  <!--     <color rgba="1.0 1.0 1.0 1.0"/> -->
  <!-- </material> -->
  <!-- <material name="orbita2dmetal"> -->
  <!--     <color rgba="0.85 0.85 0.85 1.0"/> -->
  <!-- </material> -->
  <!-- <material name="orbita2dgrey"> -->
  <!--     <color rgba="0.8 0.8 0.8 1.0"/> -->
  <!-- </material> -->
  <!-- <material name="orbita3d_yellow"> -->
  <!--     <color rgba="0.8 0.8 0.0 1"/> -->
  <!-- </material> -->
  <!-- <material name="orbita3d_grey"> -->
  <!--     <color rgba="0.8 0.8 0.8 1"/> -->
  <!-- </material> -->
  <material name="camblack">
    <color rgba="0.2 0.2 0.2 1"/>
  </material>
  <material name="neckwhite">
    <color rgba="0.9 0.9 0.9 1"/>
  </material>
  <!-- URDF definition is so stupid we have to do that... -->
  <!-- <material name="gripperblack"> -->
  <!--     <color rgba="0.4 0.4 0.4 1"/> -->
  <!-- </material> -->
  <!-- <material name="gripperwhite"> -->
  <!--     <color rgba="0.9 0.9 0.9 1"/> -->
  <!-- </material> -->
  <!-- <material name="reachy_yellow"> -->
  <!--     <color rgba="0.8 0.8 0.0 1"/> -->
  <!-- </material> -->
  <!-- <material name="reachy_grey"> -->
  <!--     <color rgba="0.8 0.8 0.8 1"/> -->
  <!-- </material> -->
  <!-- <material name="reachy_metal"> -->
  <!--     <color rgba="0.85 0.85 0.85 1.0"/> -->
  <!-- </material> -->
  <!-- <material name="torsoblack"> -->
  <!--     <color rgba="0.5 0.5 0.5 1.0"/> -->
  <!-- </material> -->
  <!-- <material name="eyewhite"> -->
  <!--     <color rgba="1.0 1.0 1.0 1.0"/> -->
  <!-- </material> -->
  <!-- <material name="orbita2dmetal"> -->
  <!--     <color rgba="0.85 0.85 0.85 1.0"/> -->
  <!-- </material> -->
  <!-- <material name="orbita2dgrey"> -->
  <!--     <color rgba="0.8 0.8 0.8 1.0"/> -->
  <!-- </material> -->
  <!-- <material name="orbita3d_yellow"> -->
  <!--     <color rgba="0.8 0.8 0.0 1"/> -->
  <!-- </material> -->
  <!-- <material name="orbita3d_grey"> -->
  <!--     <color rgba="0.8 0.8 0.8 1"/> -->
  <!-- </material> -->
  <!-- config  -->
  <!-- <link name="world" /> -->
  <!-- <joint name="world_joint" type="fixed"> -->
  <!--   <origin xyz="0 0 1.0" rpy="0 0 0" /> -->
  <!--   <parent link="world" /> -->
  <!--   <child link="torso" /> -->
  <!-- </joint> -->
  <link name="world"/>
  <joint name="world_joint" type="fixed">
    <origin rpy="0 0 0" xyz="0 0 0.0"/>
    <parent link="world"/>
    <child link="base_link"/>
  </joint>
  <link name="base_link">
    <visual>
      <origin rpy="0 0 0" xyz="0 0 0"/>
      <geometry>
        <mesh filename="file:///home/reachy/reachy_ws/install/reachy_description/share/reachy_description/meshes/mobile_base_visual.dae"/>
      </geometry>
      <material name="reachy_grey">
        <color rgba="0.8 0.8 0.8 1"/>
      </material>
    </visual>
    <collision>
      <origin rpy="0 0 0" xyz="0 0 0.13045"/>
      <geometry>
        <cylinder length="0.2609" radius="0.245"/>
      </geometry>
    </collision>
    <inertial>
      <origin rpy="0 0 0" xyz="0.008 -0.00048 0.112"/>
      <mass value="24.0"/>
      <inertia ixx="0.40791094" ixy="-0.00167148" ixz="-0.00178789" iyx="-0.00167148" iyy="0.4236827" iyz="0.00026596" izx="-0.00178789" izy="0.00026596" izz="0.70990763"/>
    </inertial>
  </link>
  <!-- <joint name="base_link_joint" type="fixed"> -->
  <!-- 	<origin xyz="1 0 0" rpy="0 0 0"/> -->
  <!-- 	<parent link="world"/> -->
  <!-- 	<child link="base_link"/> -->
  <!-- </joint> -->
  <link name="back_bar">
    <visual>
      <origin rpy="0 0 0" xyz="0 0 0.318"/>
      <geometry>
        <box size="0.04 0.04 0.636"/>
      </geometry>
      <material name="reachy_grey">
        <color rgba="0.8 0.8 0.8 1"/>
      </material>
    </visual>
    <collision>
      <origin rpy="0 0 0" xyz="0 0 0.318"/>
      <geometry>
        <box size="0.04 0.04 0.636"/>
      </geometry>
    </collision>
  </link>
  <link name="left_bar">
    <visual>
      <origin rpy="0 0 0" xyz="0.0 0 0.3254603066811681"/>
      <geometry>
        <box size="0.04 0.04 0.6509206133623362"/>
      </geometry>
      <material name="reachy_grey">
        <color rgba="0.8 0.8 0.8 1"/>
      </material>
    </visual>
    <collision>
      <origin rpy="0 0 0" xyz="0.0 0 0.3254603066811681"/>
      <geometry>
        <box size="0.04 0.04 0.6509206133623362"/>
      </geometry>
    </collision>
  </link>
  <link name="right_bar">
    <visual>
      <origin rpy="0 0 0" xyz="0.0 0 0.3254603066811681"/>
      <geometry>
        <box size="0.04 0.04 0.6509206133623362"/>
      </geometry>
      <material name="reachy_grey">
        <color rgba="0.8 0.8 0.8 1"/>
      </material>
    </visual>
    <collision>
      <origin rpy="0 0 0" xyz="0.0 0 0.3254603066811681"/>
      <geometry>
        <box size="0.04 0.04 0.6509206133623362"/>
      </geometry>
    </collision>
  </link>
  <joint name="back_bar_joint" type="fixed">
    <!-- <origin xyz="-0.122 0 0.057" rpy="0 0 0"/> -->
    <origin rpy="0 0 0" xyz="-0.122 0 0.164"/>
    <parent link="base_link"/>
    <child link="back_bar"/>
  </joint>
  <joint name="left_bar_joint" type="fixed">
    <!-- <origin xyz="0.080966 0.11718 0.057" rpy="0 ${-pi/2+atan2(back_bar_length,bar_small_triangle_base)} ${bar_angle}"/> -->
    <origin rpy="0 -0.2145247569990152 0.479232506012603" xyz="0.080966 0.117182 0.164"/>
    <parent link="base_link"/>
    <child link="left_bar"/>
  </joint>
  <joint name="right_bar_joint" type="fixed">
    <!-- <origin xyz="0.080966 -0.11718 0.057" rpy="0 ${-pi/2+atan2(back_bar_length,bar_small_triangle_base)} ${-bar_angle}"/> -->
    <origin rpy="0 -0.2145247569990152 -0.479232506012603" xyz="0.080966 -0.117182 0.164"/>
    <parent link="base_link"/>
    <child link="right_bar"/>
  </joint>
  <!-- TORSO -->
  <link name="torso">
    <visual>
      <origin rpy="0 0 0" xyz="0 0 0 "/>
      <geometry>
        <!-- <mesh filename="package://reachy_description/meshes/torso_visual_high.dae" /> -->
        <mesh filename="file:///home/reachy/reachy_ws/install/reachy_description/share/reachy_description/meshes/torso_visual_high.dae"/>
      </geometry>
    </visual>
    <inertial>
      <!-- <origin xyz="-0.098614 -0.000471 -0.018363" rpy="0 0 0"/> -->
      <origin rpy="0 0 0" xyz="-0.051614 -0.000471 -0.018363"/>
      <mass value="6.314"/>
      <inertia ixx="0.07397673" ixy="-4.624e-4" ixz="-0.00175905" iyx="-0.00046237" iyy="0.04454533" iyz="0.00008675" izx="-0.00175905" izy="0.00008675" izz="0.05494939"/>
    </inertial>
    <collision>
      <origin rpy="0 0 0" xyz="0 0 0 "/>
      <geometry>
        <!-- <mesh filename="package://reachy_description/meshes/torso_collider_no_cone.dae" /> -->
        <mesh filename="file:///home/reachy/reachy_ws/install/reachy_description/share/reachy_description/meshes/torso_collider_no_cone.dae"/>
      </geometry>
    </collision>
  </link>
  <joint name="torso_base" type="fixed">
    <origin rpy="0 0 0" xyz="0.0768 0 0.8360000000000001"/>
    <parent link="back_bar"/>
    <child link="torso"/>
  </joint>
  <link name="logo">
    <inertial>
      <origin rpy="0.0 0.0 0.0" xyz="0.0 0.0 0.0"/>
      <mass value="0.001"/>
      <inertia ixx="1.0e-6" ixy="1.0e-8" ixz="1.0e-8" iyy="1.0e-6" iyz="1.0e-8" izz="1.0e-6"/>
    </inertial>
  </link>
  <joint name="logo_joint" type="fixed">
    <origin rpy="0 0 0" xyz="0.047 0 0.0"/>
    <parent link="torso"/>
    <child link="logo"/>
  </joint>
  <!-- <gazebo reference="torso"> -->
  <!--   <!-\- <material>Gazebo/Black</material> -\-> -->
  <!--   <static>true</static> -->
  <!-- </gazebo> -->
  <!--
      Orbita3d

    link                         (joint)

    ${parent}                    (${name}_base_joint) fixed
      ${name}_base_link          (${name}_roll) revolute
        ${name}_dummy_link1      (${name}_pitch) revolute
          ${name}_dummy_link2    (${name}_yaw) revolute
            ${name}_link         (${name}_ball_joint) fixed
              ${name}_ball_link
    -->
  <link name="neck_dummy_link1">
    <inertial>
      <mass value="0.005"/>
      <origin rpy="0 0 0" xyz="0 0 0"/>
      <inertia ixx="2.5416666666666668e-06" ixy="0.0" ixz="0.0" iyy="2.5416666666666668e-06" iyz="0.0" izz="3e-06"/>
    </inertial>
  </link>
  <link name="neck_dummy_link2">
    <inertial>
      <mass value="0.005"/>
      <origin rpy="0 0 0" xyz="0 0 0"/>
      <inertia ixx="2.5416666666666668e-06" ixy="0.0" ixz="0.0" iyy="2.5416666666666668e-06" iyz="0.0" izz="3e-06"/>
    </inertial>
  </link>
  <link name="neck_link">
    <!-- <visual> -->
    <!-- 	<origin xyz="0 0 0" rpy="0 0 0"/> -->
    <!-- 	<geometry> -->
    <!--     <cylinder length="${length}" radius="${radius}"/> -->
    <!-- 	</geometry> -->
    <!-- 	<xacro:orbita3d_grey/> -->
    <!-- </visual> -->
    <!-- <collision> -->
    <!-- 	<origin xyz="0 0 ${length/2}" rpy="0 0 0"/> -->
    <!-- 	<geometry> -->
    <!--     <cylinder length="${length}" radius="${radius}"/> -->
    <!-- 	</geometry> -->
    <!-- </collision> -->
    <inertial>
      <mass value="0.49"/>
      <origin rpy="0 0 0" xyz="0 0 -0.025"/>
      <inertia ixx="0.00024908333333333336" ixy="0.0" ixz="0.0" iyy="0.00024908333333333336" iyz="0.0" izz="0.000294"/>
    </inertial>
  </link>
  <link name="neck_ball_link">
    <!-- <visual> -->
    <!-- 	<origin xyz="0 0 0" rpy="0 0 0"/> -->
    <!-- 	<geometry> -->
    <!--     <sphere radius="${radius*1.2}"/> -->
    <!-- 	</geometry> -->
    <!-- 	<xacro:orbita3d_grey/> -->
    <!-- </visual> -->
    <!-- <collision> -->
    <!-- 	<origin xyz="0 0 0" rpy="0 0 0"/> -->
    <!-- 	<geometry> -->
    <!--     <sphere radius="${radius*1.2}"/> -->
    <!-- 	</geometry> -->
    <!-- </collision> -->
    <!-- <xacro:inertial_sphere mass="${mass*0.5}" diameter="${2*radius*1.2}"/> -->
    <inertial>
      <origin rpy="0.0 0.0 0.0" xyz="0.0 0.0 0.0"/>
      <mass value="0.001"/>
      <inertia ixx="1.0e-6" ixy="1.0e-8" ixz="1.0e-8" iyy="1.0e-6" iyz="1.0e-8" izz="1.0e-6"/>
    </inertial>
  </link>
  <joint name="neck_ball_joint" type="fixed">
    <origin rpy="0 0 0" xyz="0 0 0"/>
    <parent link="neck_link"/>
    <child link="neck_ball_link"/>
  </joint>
  <link name="neck_base_link">
    <!-- <visual> -->
    <!-- 	<origin xyz="0 0 0.0672" rpy="0 0 0"/> -->
    <!-- 	<geometry> -->
    <!--     <cylinder radius="0.0278" length="0.0336"/> -->
    <!-- 	</geometry> -->
    <!-- 	<xacro:orbita3d_grey/> -->
    <!-- </visual> -->
    <inertial>
      <origin rpy="0.0 0.0 0.0" xyz="0.0 0.0 0.0"/>
      <mass value="0.001"/>
      <inertia ixx="1.0e-6" ixy="1.0e-8" ixz="1.0e-8" iyy="1.0e-6" iyz="1.0e-8" izz="1.0e-6"/>
    </inertial>
  </link>
  <joint name="neck_base_joint" type="fixed">
    <origin rpy="0 0.17453292519943295 0.0" xyz="0.0 0 0.125"/>
    <parent link="torso"/>
    <child link="neck_base_link"/>
  </joint>
  <link name="neck_out_link">
    <inertial>
      <origin rpy="0.0 0.0 0.0" xyz="0.0 0.0 0.0"/>
      <mass value="0.001"/>
      <inertia ixx="1.0e-6" ixy="1.0e-8" ixz="1.0e-8" iyy="1.0e-6" iyz="1.0e-8" izz="1.0e-6"/>
    </inertial>
  </link>
  <joint name="neck_out_joint" type="fixed">
    <!-- <origin xyz="0 0 0" rpy="3.141592 0 0"/> -->
    <origin rpy="0 0 0" xyz="0 0 0"/>
    <parent link="neck_ball_link"/>
    <child link="neck_out_link"/>
  </joint>
  <joint name="neck_roll" type="revolute">
    <!-- <origin xyz="${xyz}" rpy="${rpy}"/> -->
    <origin rpy="0 0 0" xyz="0 0 0"/>
    <!-- <parent link="${parent}"/> -->
    <parent link="neck_base_link"/>
    <child link="neck_dummy_link1"/>
    <axis xyz="1 0 0"/>
    <limit effort="1000.0" lower="-0.35" upper="0.35" velocity="100.0"/>
    <dynamics damping="0.1" friction="0.1"/>
  </joint>
  <joint name="neck_pitch" type="revolute">
    <origin rpy="0 0 0" xyz="0 0 0"/>
    <parent link="neck_dummy_link1"/>
    <child link="neck_dummy_link2"/>
    <axis xyz="0 1 0"/>
    <limit effort="1000.0" lower="-0.35" upper="0.35" velocity="100.0"/>
    <dynamics damping="0.1" friction="0.1"/>
  </joint>
  <joint name="neck_yaw" type="revolute">
    <origin rpy="0 0 0" xyz="0 0 0"/>
    <parent link="neck_dummy_link2"/>
    <child link="neck_link"/>
    <axis xyz="0 0 1"/>
    <limit effort="1000.0" lower="-1.57" upper="1.57" velocity="100.0"/>
    <dynamics damping="0.1" friction="0.1"/>
  </joint>
  <ros2_control name="neck" type="system">
    <hardware>
      <!-- Standard ROS fake system -->
      <!-- <plugin>fake_components/GenericSystem</plugin> -->
      <!-- Pollen controller fake system -->
      <plugin>orbita3d_system_hwi/Orbita3dSystem</plugin>
      <param name="config_file">/home/reachy/reachy_ws/install/orbita3d_description/share/orbita3d_description/config/fake.yaml</param>
    </hardware>
    <gpio name="neck">
      <state_interface name="torque">
        <param name="initial_value">0.0</param>
      </state_interface>
      <command_interface name="torque"/>
    </gpio>
    <joint name="neck_roll">
      <state_interface name="position">
        <param name="initial_value">0.0</param>
      </state_interface>
      <state_interface name="velocity">
        <param name="initial_value">0.0</param>
      </state_interface>
      <state_interface name="effort">
        <param name="initial_value">0.0</param>
      </state_interface>
      <command_interface name="position"/>
    </joint>
    <joint name="neck_pitch">
      <state_interface name="position">
        <param name="initial_value">0.0</param>
      </state_interface>
      <state_interface name="velocity">
        <param name="initial_value">0.0</param>
      </state_interface>
      <state_interface name="effort">
        <param name="initial_value">0.0</param>
      </state_interface>
      <command_interface name="position"/>
    </joint>
    <joint name="neck_yaw">
      <state_interface name="position">
        <param name="initial_value">0.0</param>
      </state_interface>
      <state_interface name="velocity">
        <param name="initial_value">0.0</param>
      </state_interface>
      <state_interface name="effort">
        <param name="initial_value">0.0</param>
      </state_interface>
      <command_interface name="position"/>
    </joint>
    <gpio name="neck_raw_motor_1">
      <state_interface name="speed_limit"/>
      <command_interface name="speed_limit"/>
      <state_interface name="torque_limit"/>
      <command_interface name="torque_limit"/>
      <state_interface name="p_gain"/>
      <command_interface name="p_gain"/>
      <state_interface name="i_gain"/>
      <command_interface name="i_gain"/>
      <state_interface name="d_gain"/>
      <command_interface name="d_gain"/>
    </gpio>
    <gpio name="neck_raw_motor_2">
      <state_interface name="speed_limit"/>
      <command_interface name="speed_limit"/>
      <state_interface name="torque_limit"/>
      <command_interface name="torque_limit"/>
      <state_interface name="p_gain"/>
      <command_interface name="p_gain"/>
      <state_interface name="i_gain"/>
      <command_interface name="i_gain"/>
      <state_interface name="d_gain"/>
      <command_interface name="d_gain"/>
    </gpio>
    <gpio name="neck_raw_motor_3">
      <state_interface name="speed_limit"/>
      <command_interface name="speed_limit"/>
      <state_interface name="torque_limit"/>
      <command_interface name="torque_limit"/>
      <state_interface name="p_gain"/>
      <command_interface name="p_gain"/>
      <state_interface name="i_gain"/>
      <command_interface name="i_gain"/>
      <state_interface name="d_gain"/>
      <command_interface name="d_gain"/>
    </gpio>
  </ros2_control>
  <joint name="neck_fixed" type="fixed">
    <origin rpy="0.0 0.0 0.0" xyz="0 0 0"/>
    <parent link="neck_out_link"/>
    <child link="head"/>
  </joint>
  <!-- Head Links -->
  <link name="head">
    <inertial>
      <origin rpy="0.0 0.0 0.0" xyz="0.0116978 -0.00022144 0.0611705"/>
      <mass value="0.325"/>
      <inertia ixx="0.00085265" ixy="-0.00000298" ixz="0.00000932" iyx="-0.00000298" iyy="0.00063136" iyz="-0.000000039" izx="0.00000932" izy="-0.000000039" izz="0.0008951"/>
    </inertial>
    <visual>
      <origin rpy="0.0 0.0 0.0" xyz="0.00 0.0 0.0"/>
      <geometry>
        <mesh filename="file:///home/reachy/reachy_ws/install/reachy_description/share/reachy_description/meshes/head_visual.dae"/>
      </geometry>
    </visual>
    <collision>
      <!-- <origin xyz="0.0 0.0 0.05" rpy="0.0 0.0 0.0"/> -->
      <origin rpy="0.0 0.0 0.0" xyz="0.0 0.0 0.0"/>
      <geometry>
        <!-- <box size="0.12 0.162 0.1"/> -->
        <mesh filename="file:///home/reachy/reachy_ws/install/reachy_description/share/reachy_description/meshes/head_collider.dae"/>
      </geometry>
    </collision>
  </link>
  <link name="head_base">
    <inertial>
      <origin rpy="0.0 0.0 0.0" xyz="0.0 0.0 0.0"/>
      <mass value="0.001"/>
      <inertia ixx="1.0e-6" ixy="1.0e-8" ixz="1.0e-8" iyy="1.0e-6" iyz="1.0e-8" izz="1.0e-6"/>
    </inertial>
  </link>
  <joint name="head_base_fixed" type="fixed">
    <origin rpy="0.0 0.0 0" xyz="0.0 0 0.0"/>
    <parent link="head"/>
    <child link="head_base"/>
  </joint>
  <!-- <link name="head_tracker"> -->
  <!--   <visual name=""> -->
  <!--     <origin xyz="0 0 0" rpy="0.0 0.0 0.0"/> -->
  <!--     <geometry> -->
  <!-- 	  <cylinder length="0.04" radius="0.04"/> -->
  <!--     </geometry> -->
  <!-- 	<material name="camblack"/> -->
  <!--   </visual> -->
  <!-- </link> -->
  <!-- <joint name="head_tracker_fixed" type="fixed"> -->
  <!--   <origin xyz="-0.030 0.0 0.111" rpy="0.0 0.0 0"/> -->
  <!--   <parent link="head" /> -->
  <!--   <child link="head_tracker" /> -->
  <!-- </joint> -->
  <link name="head_tip">
    <inertial>
      <origin rpy="0.0 0.0 0.0" xyz="0.0 0.0 0.0"/>
      <mass value="0.001"/>
      <inertia ixx="1.0e-6" ixy="1.0e-8" ixz="1.0e-8" iyy="1.0e-6" iyz="1.0e-8" izz="1.0e-6"/>
    </inertial>
  </link>
  <joint name="head_tip_fixed" type="fixed">
    <!-- between the cameras -->
    <origin rpy="0 0.0 0" xyz="0.057 0.0 0.056"/>
    <!-- Rotation center -->
    <!-- <origin xyz="0.0 0 0.0" rpy="0.0 0.0 0"/> -->
    <parent link="head"/>
    <child link="head_tip"/>
  </joint>
  <!-- <link name="camera_optical_left" > -->
  <!-- </link> -->
  <!-- <joint name="camera_optical_left" type="fixed"> -->
  <!--   <!-\- between the cameras -\-> -->
  <!--   <!-\- <origin xyz="0.030 0.022 0.085" rpy="-1.57 0.0 -1.57"/> -\-> -->
  <!--   <origin xyz="0.03531 0.0325 0.056" rpy="${-pi/2.0} 0 ${-pi/2.0}"/> -->
  <!--   <!-\- Rotation center -\-> -->
  <!--   <!-\- <origin xyz="0.0 0 0.0" rpy="0.0 0.0 0"/> -\-> -->
  <!--   <parent link="head" /> -->
  <!--   <child link="camera_optical_left" /> -->
  <!-- </joint> -->
  <!-- Reachy Cameras -->
  <joint name="left_cam_fixed" type="fixed">
    <origin rpy="0.0 0.0  -0.0" xyz="0.03531 0.0325 0.056"/>
    <parent link="head"/>
    <child link="left_camera"/>
  </joint>
  <link name="left_camera">
    <inertial>
      <mass value="1e-5"/>
      <origin rpy="0 0 0" xyz="0 0 0"/>
      <inertia ixx="1e-6" ixy="0" ixz="0" iyy="1e-6" iyz="0" izz="1e-6"/>
    </inertial>
  </link>
  <link name="left_camera_optical">
    <inertial>
      <origin rpy="0.0 0.0 0.0" xyz="0.0 0.0 0.0"/>
      <mass value="0.001"/>
      <inertia ixx="1.0e-6" ixy="1.0e-8" ixz="1.0e-8" iyy="1.0e-6" iyz="1.0e-8" izz="1.0e-6"/>
    </inertial>
  </link>
  <joint name="left_camera_optical_joint" type="fixed">
    <!-- these values have to be these values otherwise the gazebo camera
             image won't be aligned properly with the frame it is supposedly
             originating from -->
    <origin rpy="-1.5707963267948966 0 -1.5707963267948966" xyz="0 0 0"/>
    <parent link="left_camera"/>
    <child link="left_camera_optical"/>
  </joint>
  <joint name="right_cam_fixed" type="fixed">
    <origin rpy="0.0 0.0 0.0" xyz="0.03531 -0.0325 0.056"/>
    <parent link="head"/>
    <child link="right_camera"/>
  </joint>
  <link name="right_camera">
    <inertial>
      <mass value="1e-5"/>
      <origin rpy="0 0 0" xyz="0 0 0"/>
      <inertia ixx="1e-6" ixy="0" ixz="0" iyy="1e-6" iyz="0" izz="1e-6"/>
    </inertial>
  </link>
  <link name="right_camera_optical">
      </link>
  <joint name="right_camera_optical_joint" type="fixed">
    <!-- these values have to be these values otherwise the gazebo camera
             image won't be aligned properly with the frame it is supposedly
             originating from -->
    <origin rpy="-1.5707963267948966 0 -1.5707963267948966" xyz="0 0 0"/>
    <!-- <origin xyz="0.03531 -0.0325 0.056" rpy="${-pi/2.0} 0 ${-pi/2.0}"/> -->
    <parent link="right_camera"/>
    <child link="right_camera_optical"/>
  </joint>
  <!-- URDF definition is so stupid we have to do that... -->
  <!-- <material name="gripperblack"> -->
  <!--     <color rgba="0.4 0.4 0.4 1"/> -->
  <!-- </material> -->
  <!-- <material name="gripperwhite"> -->
  <!--     <color rgba="0.9 0.9 0.9 1"/> -->
  <!-- </material> -->
  <!-- <material name="reachy_yellow"> -->
  <!--     <color rgba="0.8 0.8 0.0 1"/> -->
  <!-- </material> -->
  <!-- <material name="reachy_grey"> -->
  <!--     <color rgba="0.8 0.8 0.8 1"/> -->
  <!-- </material> -->
  <!-- <material name="reachy_metal"> -->
  <!--     <color rgba="0.85 0.85 0.85 1.0"/> -->
  <!-- </material> -->
  <!-- <material name="torsoblack"> -->
  <!--     <color rgba="0.5 0.5 0.5 1.0"/> -->
  <!-- </material> -->
  <!-- <material name="eyewhite"> -->
  <!--     <color rgba="1.0 1.0 1.0 1.0"/> -->
  <!-- </material> -->
  <!-- <material name="orbita2dmetal"> -->
  <!--     <color rgba="0.85 0.85 0.85 1.0"/> -->
  <!-- </material> -->
  <!-- <material name="orbita2dgrey"> -->
  <!--     <color rgba="0.8 0.8 0.8 1.0"/> -->
  <!-- </material> -->
  <!-- <material name="orbita3d_yellow"> -->
  <!--     <color rgba="0.8 0.8 0.0 1"/> -->
  <!-- </material> -->
  <!-- <material name="orbita3d_grey"> -->
  <!--     <color rgba="0.8 0.8 0.8 1"/> -->
  <!-- </material> -->
  <!-- URDF definition is so stupid we have to do that... -->
  <!-- <material name="gripperblack"> -->
  <!--     <color rgba="0.4 0.4 0.4 1"/> -->
  <!-- </material> -->
  <!-- <material name="gripperwhite"> -->
  <!--     <color rgba="0.9 0.9 0.9 1"/> -->
  <!-- </material> -->
  <!-- <material name="reachy_yellow"> -->
  <!--     <color rgba="0.8 0.8 0.0 1"/> -->
  <!-- </material> -->
  <!-- <material name="reachy_grey"> -->
  <!--     <color rgba="0.8 0.8 0.8 1"/> -->
  <!-- </material> -->
  <!-- <material name="reachy_metal"> -->
  <!--     <color rgba="0.85 0.85 0.85 1.0"/> -->
  <!-- </material> -->
  <!-- <material name="torsoblack"> -->
  <!--     <color rgba="0.5 0.5 0.5 1.0"/> -->
  <!-- </material> -->
  <!-- <material name="eyewhite"> -->
  <!--     <color rgba="1.0 1.0 1.0 1.0"/> -->
  <!-- </material> -->
  <!-- <material name="orbita2dmetal"> -->
  <!--     <color rgba="0.85 0.85 0.85 1.0"/> -->
  <!-- </material> -->
  <!-- <material name="orbita2dgrey"> -->
  <!--     <color rgba="0.8 0.8 0.8 1.0"/> -->
  <!-- </material> -->
  <!-- <material name="orbita3d_yellow"> -->
  <!--     <color rgba="0.8 0.8 0.0 1"/> -->
  <!-- </material> -->
  <!-- <material name="orbita3d_grey"> -->
  <!--     <color rgba="0.8 0.8 0.8 1"/> -->
  <!-- </material> -->
  <!-- <!-\- Orbita2d config -\-> -->
  <!-- <xacro:arg name="orbita2d_shoulder_config" default="$(find
    orbita2d_description)/config/fake.yaml"/> -->
  <!-- <xacro:arg name="orbita2d_elbow_config" default="$(find
    orbita2d_description)/config/fake.yaml"/> -->
  <!-- <!-\- Orbita3d config -\-> -->
  <!-- <xacro:arg name="orbita3d_wrist_config" default="$(find
    orbita3d_controller)/config/fake.yaml"/> -->
  <!-- ARM PARAMETERS -->
  <link name="r_shoulder_base_link">
    <inertial>
      <origin rpy="0.0 0.0 0.0" xyz="0.0 0.0 0.0"/>
      <mass value="0.001"/>
      <inertia ixx="1.0e-6" ixy="1.0e-8" ixz="1.0e-8" iyy="1.0e-6" iyz="1.0e-8" izz="1.0e-6"/>
    </inertial>
  </link>
  <joint name="r_shoulder_base_joint" type="fixed">
    <!-- <origin xyz="${arm_offset_x} ${arm_offset_y*reflect} ${arm_offset_z}" rpy="${(1.5707963267948966+(virtual_shoulder_roll_offset - arm_offset_roll))*reflect} 0 ${arm_offset_yaw*reflect}" /> -->
    <origin rpy="1.3089969389957472 0 0.17453292519943295" xyz="0.0 -0.2 0.0"/>
    <parent link="torso"/>
    <child link="r_shoulder_base_link"/>
  </joint>
  <!--
      Orbita 2 dof

    link                         (joint)

    ${parent}                    (${name}_dummy_1) fixed
      ${name}_dummy_link1        (${name}_dummy_2) fixed
        ${name}_dummy_link2      (${name}_joint1) revolute
          ${name}_first_link     (${name}_joint2) revolute
      	    ${name}_ball_link    (${name}_dummy_out) fixed
	      ${name}_fix_link


    -->
  <!-- used to "place" the joint with the correct axis. For some reason rotation of the inertia matrix does not work... -->
  <link name="r_shoulder_dummy_link1">
    <inertial>
      <origin rpy="0.0 0.0 0.0" xyz="0.0 0.0 0.0"/>
      <mass value="0.001"/>
      <inertia ixx="1.0e-6" ixy="1.0e-8" ixz="1.0e-8" iyy="1.0e-6" iyz="1.0e-8" izz="1.0e-6"/>
    </inertial>
  </link>
  <joint name="r_shoulder_dummy_1" type="fixed">
    <origin rpy="0 0 0" xyz="0 0 0"/>
    <parent link="r_shoulder_base_link"/>
    <child link="r_shoulder_dummy_link1"/>
  </joint>
  <link name="r_shoulder_dummy_link2">
    <inertial>
      <origin rpy="0.0 0.0 0.0" xyz="0.0 0.0 0.0"/>
      <mass value="0.001"/>
      <inertia ixx="1.0e-6" ixy="1.0e-8" ixz="1.0e-8" iyy="1.0e-6" iyz="1.0e-8" izz="1.0e-6"/>
    </inertial>
  </link>
  <!-- used to rotatate the joint to respect the conventional axis -->
  <joint name="r_shoulder_dummy_2" type="fixed">
    <origin rpy="-1.5707963267948966 0 0" xyz="0 0 0"/>
    <!-- <origin xyz="0 0 0" rpy="0 0 0"/> -->
    <parent link="r_shoulder_dummy_link1"/>
    <child link="r_shoulder_dummy_link2"/>
  </joint>
  <link name="r_shoulder_first_link">
    <visual>
      <origin rpy="1.5707963267948966 0 0" xyz="0 0 0"/>
      <geometry>
        <!-- <mesh filename="file://$(find arm_description)/meshes/Orbita2D_ball.dae" /> -->
        <mesh filename="file:///home/reachy/reachy_ws/install/arm_description/share/arm_description/meshes/2D_sphere_visual.dae"/>
      </geometry>
    </visual>
    <!-- <collision> -->
    <!--   <geometry> -->
    <!--     <sphere radius="0.0425"/> -->
    <!--   </geometry> -->
    <!-- </collision> -->
    <inertial>
      <!-- <origin xyz="0.0 0 0" rpy="1.5707963267948966 0 0"/> -->
      <!-- rotation does not work? -->
      <origin rpy="0 0 0" xyz="0.000096 -0.000015 -0.01777"/>
      <mass value="0.487"/>
      <inertia ixx="0.000577881945" ixy="-8.085000000000001e-7" ixz="-6.962790000000001e-7" iyx="-8.085000000000001e-7" iyy="0.000573075516" iyz="2.44386e-7" izx="-6.962790000000001e-7" izy="2.44386e-7" izz="0.000243343676"/>
    </inertial>
  </link>
  <!-- First joint  -->
  <joint name="r_shoulder_pitch" type="revolute">
    <origin rpy="0 0 0" xyz="0 0 0"/>
    <!-- <parent link="${parent}"/> -->
    <parent link="r_shoulder_dummy_link2"/>
    <child link="r_shoulder_first_link"/>
    <axis xyz="0 1 0"/>
    <!-- <axis xyz="0 0 -1"/> -->
    <limit effort="1000.0" lower="-1.5707963267948966" upper="1.5707963267948966" velocity="100.0"/>
    <safety_controller k_position="500" k_velocity="500" soft_lower_limit="-3.141592" soft_upper_limit="3.1415"/>
    <dynamics damping="0.1" friction="0.1"/>
  </joint>
  <!-- <!-\- Used to get back to the correct orientation -\-> -->
  <!-- <link name="${name}_dummy_link3"> -->
  <!-- </link> -->
  <!-- <joint name="${name}_dummy_3" type="fixed"> -->
  <!--   <!-\- <origin xyz="0 0 0" rpy="-1.5707963267948966 0 0"/> -\-> -->
  <!--   <origin xyz="0 0 0" rpy="3.141592653589793 0 0"/> -->
  <!--   <parent link="${name}_first_link"/> -->
  <!--   <child link="${name}_dummy_link3"/> -->
  <!-- </joint> -->
  <!-- Output link -->
  <link name="r_shoulder_ball_link">
    <inertial>
      <origin rpy="0.0 0.0 0.0" xyz="0.0 0.0 0.0"/>
      <mass value="0.001"/>
      <inertia ixx="1.0e-6" ixy="1.0e-8" ixz="1.0e-8" iyy="1.0e-6" iyz="1.0e-8" izz="1.0e-6"/>
    </inertial>
  </link>
  <joint name="r_shoulder_roll" type="revolute">
    <origin rpy=" 0 0 0" xyz="0 0 0"/>
    <parent link="r_shoulder_first_link"/>
    <child link="r_shoulder_ball_link"/>
    <axis xyz="1 0 0"/>
    <!-- <axis xyz="1 0 0"/> -->
    <limit effort="1000.0" lower="-1.5707963267948966" upper="0.0" velocity="100.0"/>
    <safety_controller k_position="500" k_velocity="500" soft_lower_limit="-3.1415" soft_upper_limit="3.1415"/>
    <dynamics damping="0.1" friction="0.1"/>
  </joint>
  <link name="r_shoulder_fix_link">
    <inertial>
      <origin rpy="0.0 0.0 0.0" xyz="0.0 0.0 0.0"/>
      <mass value="0.001"/>
      <inertia ixx="1.0e-6" ixy="1.0e-8" ixz="1.0e-8" iyy="1.0e-6" iyz="1.0e-8" izz="1.0e-6"/>
    </inertial>
  </link>
  <!-- used to rotate the joint to respect the conventional axis -->
  <joint name="r_shoulder_dummy_out" type="fixed">
    <origin rpy="1.5707963267948966 0 0" xyz="0 0 0"/>
    <!-- <origin xyz="0 0 0" rpy="0 0 0"/> -->
    <parent link="r_shoulder_ball_link"/>
    <child link="r_shoulder_fix_link"/>
  </joint>
  <!-- <xacro:orbita2d_control -->
  <!--   name="${name}" -->
  <!--   joint1="${joint1}" joint2="${joint2}" -->
  <!--   config_file="${config_file}" -->
  <!-- /> -->
  <link name="r_elbow_arm_link">
    <visual>
      <origin rpy="0 0 0" xyz="0 0 0"/>
      <geometry>
        <!-- <mesh filename="package://arm_description/meshes/upper_arm_visual.dae" /> -->
        <mesh filename="file:///home/reachy/reachy_ws/install/arm_description/share/arm_description/meshes/upper_arm_visual.dae"/>
      </geometry>
    </visual>
    <collision>
      <!-- <origin xyz="0 0 ${arm_length/2}" rpy="0 0 0"/> -->
      <origin rpy="0 0 0" xyz="0 0 0"/>
      <geometry>
        <!-- <mesh filename="package://arm_description/meshes/upper_arm_collider.dae" /> -->
        <mesh filename="file:///home/reachy/reachy_ws/install/arm_description/share/arm_description/meshes/upper_arm_collider.dae"/>
      </geometry>
    </collision>
    <inertial>
      <origin rpy="0 0 0" xyz="-0.000669 0.000509 0.144798"/>
      <mass value="1.620"/>
      <inertia ixx="0.007864" ixy="0.000005410021" ixz="-0.000117782969" iyx="0.000005410021" iyy="0.006998" iyz="0.000121931452" izx="-0.000117782969" izy="0.000121931452" izz="0.001828"/>
    </inertial>
  </link>
  <joint name="r_elbow_arm_joint" type="fixed">
    <origin rpy="0 1.5707963267948966 -1.5707963267948966" xyz="0 0 0.0"/>
    <!-- <origin xyz="0 0 0.0" rpy="0 0 0" /> -->
    <!-- <parent link="${p}_shoulder_ball_link" /> -->
    <parent link="r_shoulder_fix_link"/>
    <child link="r_elbow_arm_link"/>
  </joint>
  <link name="r_elbow_base_link">
    <inertial>
      <origin rpy="0.0 0.0 0.0" xyz="0.0 0.0 0.0"/>
      <mass value="0.001"/>
      <inertia ixx="1.0e-6" ixy="1.0e-8" ixz="1.0e-8" iyy="1.0e-6" iyz="1.0e-8" izz="1.0e-6"/>
    </inertial>
  </link>
  <!-- <joint name="${prefix}_elbow_base_joint" type="fixed"> -->
  <!--   <origin xyz="0 0 0" rpy="0 ${(1.5707963267948966 + virtual_elbow_offset_yaw)*reflect} 0" /> -->
  <!--   <parent link="${p}_shoulder_ball_link" /> -->
  <!--   <child link="${prefix}_elbow_base_link" /> -->
  <!-- </joint> -->
  <!-- <xacro:orbita2d -->
  <!--   name="${p}_elbow" parent="${prefix}_elbow_base_link" -->
  <!--   length="${forearm_length}" radius="${forearm_radius}" mass="${forearm_mass}" -->
  <!--   xyz="0 -${arm_length} 0" rpy="${1.5707963267948966} 0 0" -->
  <!--   damping="${damping}" friction="${friction}" -->
  <!--   joint1="yaw" joint2="pitch" -->
  <!--   joint1_min_angle="-${pi/2}" joint1_max_angle="${pi/2}" -->
  <!--   joint2_min_angle="-2.25" joint2_max_angle="0.1" -->
  <!-- /> -->
  <joint name="r_elbow_base_joint" type="fixed">
    <origin rpy="0 0 0" xyz="0 0 0.28"/>
    <parent link="r_elbow_arm_link"/>
    <child link="r_elbow_base_link"/>
  </joint>
  <!--
      Orbita 2 dof

    link                         (joint)

    ${parent}                    (${name}_dummy_1) fixed
      ${name}_dummy_link1        (${name}_dummy_2) fixed
        ${name}_dummy_link2      (${name}_joint1) revolute
          ${name}_first_link     (${name}_joint2) revolute
      	    ${name}_ball_link    (${name}_dummy_out) fixed
	      ${name}_fix_link


    -->
  <!-- used to "place" the joint with the correct axis. For some reason rotation of the inertia matrix does not work... -->
  <link name="r_elbow_dummy_link1">
    <inertial>
      <origin rpy="0.0 0.0 0.0" xyz="0.0 0.0 0.0"/>
      <mass value="0.001"/>
      <inertia ixx="1.0e-6" ixy="1.0e-8" ixz="1.0e-8" iyy="1.0e-6" iyz="1.0e-8" izz="1.0e-6"/>
    </inertial>
  </link>
  <joint name="r_elbow_dummy_1" type="fixed">
    <origin rpy="0 0 0" xyz="0 0 0"/>
    <parent link="r_elbow_base_link"/>
    <child link="r_elbow_dummy_link1"/>
  </joint>
  <link name="r_elbow_dummy_link2">
    <inertial>
      <origin rpy="0.0 0.0 0.0" xyz="0.0 0.0 0.0"/>
      <mass value="0.001"/>
      <inertia ixx="1.0e-6" ixy="1.0e-8" ixz="1.0e-8" iyy="1.0e-6" iyz="1.0e-8" izz="1.0e-6"/>
    </inertial>
  </link>
  <!-- used to rotatate the joint to respect the conventional axis -->
  <joint name="r_elbow_dummy_2" type="fixed">
    <origin rpy="3.141592 0 1.5707963267948966" xyz="0 0 0"/>
    <!-- <origin xyz="0 0 0" rpy="0 0 0"/> -->
    <parent link="r_elbow_dummy_link1"/>
    <child link="r_elbow_dummy_link2"/>
  </joint>
  <link name="r_elbow_first_link">
    <visual>
      <origin rpy="3.141592 0 -1.5707963267948966" xyz="0 0 0"/>
      <geometry>
        <!-- <mesh filename="file://$(find arm_description)/meshes/Orbita2D_ball.dae" /> -->
        <mesh filename="file:///home/reachy/reachy_ws/install/arm_description/share/arm_description/meshes/2D_sphere_visual.dae"/>
      </geometry>
    </visual>
    <!-- <collision> -->
    <!--   <geometry> -->
    <!--     <sphere radius="0.0425"/> -->
    <!--   </geometry> -->
    <!-- </collision> -->
    <inertial>
      <!-- <origin xyz="0.0 0 0" rpy="1.5707963267948966 0 0"/> -->
      <!-- rotation does not work? -->
      <origin rpy="0 0 0" xyz="0.000096 -0.000015 -0.01777"/>
      <mass value="0.487"/>
      <inertia ixx="0.000577881945" ixy="-8.085000000000001e-7" ixz="-6.962790000000001e-7" iyx="-8.085000000000001e-7" iyy="0.000573075516" iyz="2.44386e-7" izx="-6.962790000000001e-7" izy="2.44386e-7" izz="0.000243343676"/>
    </inertial>
  </link>
  <!-- First joint  -->
  <joint name="r_elbow_yaw" type="revolute">
    <origin rpy="0 0 0" xyz="0 0 0"/>
    <!-- <parent link="${parent}"/> -->
    <parent link="r_elbow_dummy_link2"/>
    <child link="r_elbow_first_link"/>
    <axis xyz="0 0 1"/>
    <!-- <axis xyz="0 0 -1"/> -->
    <limit effort="1000.0" lower="-1.5707963267948966" upper="1.5707963267948966" velocity="100.0"/>
    <safety_controller k_position="500" k_velocity="500" soft_lower_limit="-3.141592" soft_upper_limit="3.1415"/>
    <dynamics damping="0.1" friction="0.1"/>
  </joint>
  <!-- <!-\- Used to get back to the correct orientation -\-> -->
  <!-- <link name="${name}_dummy_link3"> -->
  <!-- </link> -->
  <!-- <joint name="${name}_dummy_3" type="fixed"> -->
  <!--   <!-\- <origin xyz="0 0 0" rpy="-1.5707963267948966 0 0"/> -\-> -->
  <!--   <origin xyz="0 0 0" rpy="3.141592653589793 0 0"/> -->
  <!--   <parent link="${name}_first_link"/> -->
  <!--   <child link="${name}_dummy_link3"/> -->
  <!-- </joint> -->
  <!-- Output link -->
  <link name="r_elbow_ball_link">
    <inertial>
      <origin rpy="0.0 0.0 0.0" xyz="0.0 0.0 0.0"/>
      <mass value="0.001"/>
      <inertia ixx="1.0e-6" ixy="1.0e-8" ixz="1.0e-8" iyy="1.0e-6" iyz="1.0e-8" izz="1.0e-6"/>
    </inertial>
  </link>
  <joint name="r_elbow_pitch" type="revolute">
    <origin rpy=" 0 0 0" xyz="0 0 0"/>
    <parent link="r_elbow_first_link"/>
    <child link="r_elbow_ball_link"/>
    <axis xyz="0 1 0"/>
    <!-- <axis xyz="1 0 0"/> -->
    <limit effort="1000.0" lower="-2.25" upper="0.1" velocity="100.0"/>
    <safety_controller k_position="500" k_velocity="500" soft_lower_limit="-3.1415" soft_upper_limit="3.1415"/>
    <dynamics damping="0.1" friction="0.1"/>
  </joint>
  <link name="r_elbow_fix_link">
    <inertial>
      <origin rpy="0.0 0.0 0.0" xyz="0.0 0.0 0.0"/>
      <mass value="0.001"/>
      <inertia ixx="1.0e-6" ixy="1.0e-8" ixz="1.0e-8" iyy="1.0e-6" iyz="1.0e-8" izz="1.0e-6"/>
    </inertial>
  </link>
  <!-- used to rotate the joint to respect the conventional axis -->
  <joint name="r_elbow_dummy_out" type="fixed">
    <origin rpy="3.141592 0 1.5707963267948966" xyz="0 0 0"/>
    <!-- <origin xyz="0 0 0" rpy="0 0 0"/> -->
    <parent link="r_elbow_ball_link"/>
    <child link="r_elbow_fix_link"/>
  </joint>
  <!-- <xacro:orbita2d_control -->
  <!--   name="${name}" -->
  <!--   joint1="${joint1}" joint2="${joint2}" -->
  <!--   config_file="${config_file}" -->
  <!-- /> -->
  <!-- <link name="${prefix}_elbow_forearm_link"> -->
  <!--   <visual> -->
  <!--   	<origin xyz="0 0 0" rpy="0 0 0"/> -->
  <!--   	<geometry> -->
  <!-- 	  <mesh filename="package://arm_description/meshes/Orbita2D_forearm.dae" /> -->
  <!--   	</geometry> -->
  <!--   </visual> -->
  <!--   <inertial> -->
  <!--   	<origin xyz="0.00092892 -0.00254548 0.14021211" rpy="0 0 0"/> -->
  <!-- 	<mass value="0.90719109"/> -->
  <!-- 	 <inertia ixx="0.00428278" ixy="-0.00000203" ixz="0.00011755" -->
  <!-- 		  iyx="-0.00000203" iyy="0.0044585" iyz="-0.00004915" -->
  <!-- 		  izx="0.00011755" izy="-0.00004915" izz="0.00047615"/> -->
  <!--   </inertial> -->
  <!-- </link> -->
  <!-- <joint name="${prefix}_elbow_forearm_joint" type="fixed"> -->
  <!--   <origin xyz="0 0 0.0" rpy="0 0 0" /> -->
  <!--   <parent link="${p}_elbow_ball_link" /> -->
  <!--   <child link="${prefix}_elbow_forearm_link" /> -->
  <!-- </joint> -->
  <link name="r_elbow_forearm_link">
    <visual>
      <origin rpy="0 0 0" xyz="0 0 0"/>
      <geometry>
        <!-- <mesh filename="package://arm_description/meshes/forearm_visual.dae" /> -->
        <mesh filename="file:///home/reachy/reachy_ws/install/arm_description/share/arm_description/meshes/forearm_visual.dae"/>
      </geometry>
    </visual>
    <collision>
      <origin rpy="0 0 0" xyz="0 0 0"/>
      <!-- <origin xyz="0 0 ${forearm_length/2}" rpy="0 0 0"/> -->
      <geometry>
        <!-- <mesh filename="package://arm_description/meshes/forearm_collider.dae" /> -->
        <mesh filename="file:///home/reachy/reachy_ws/install/arm_description/share/arm_description/meshes/forearm_collider.dae"/>
      </geometry>
    </collision>
    <inertial>
      <origin rpy="0 0 0" xyz="0.00092892 -0.00254548 0.14021211"/>
      <mass value="0.90719109"/>
      <inertia ixx="0.00428278" ixy="-0.00000203" ixz="0.00011755" iyx="-0.00000203" iyy="0.0044585" iyz="-0.00004915" izx="0.00011755" izy="-0.00004915" izz="0.00047615"/>
    </inertial>
  </link>
  <joint name="r_elbow_forearm_joint" type="fixed">
    <origin rpy="0 0 0" xyz="0 0 0.0"/>
    <!-- <parent link="${p}_elbow_ball_link" /> -->
    <parent link="r_elbow_fix_link"/>
    <child link="r_elbow_forearm_link"/>
  </joint>
  <!-- <xacro:orbita3d -->
  <!--   name="${p}_wrist" parent="${p}_elbow_ball_link" -->
  <!--   length="${wrist_length}" radius="${wrist_radius}" mass="${wrist_mass}" -->
  <!--   xyz="0 0 ${forearm_length}" rpy="${pi} 0 0" -->
  <!--   damping="${damping}" friction="${friction}" -->
  <!-- /> -->
  <!--
      Orbita3d

    link                         (joint)

    ${parent}                    (${name}_base_joint) fixed
      ${name}_base_link          (${name}_roll) revolute
        ${name}_dummy_link1      (${name}_pitch) revolute
          ${name}_dummy_link2    (${name}_yaw) revolute
            ${name}_link         (${name}_ball_joint) fixed
              ${name}_ball_link
    -->
  <link name="r_wrist_dummy_link1">
    <inertial>
      <mass value="0.001"/>
      <origin rpy="0 0 0" xyz="0 0 0"/>
      <inertia ixx="1.4166666666666668e-07" ixy="0.0" ixz="0.0" iyy="1.4166666666666668e-07" iyz="0.0" izz="2.6666666666666667e-07"/>
    </inertial>
  </link>
  <link name="r_wrist_dummy_link2">
    <inertial>
      <mass value="0.001"/>
      <origin rpy="0 0 0" xyz="0 0 0"/>
      <inertia ixx="1.4166666666666668e-07" ixy="0.0" ixz="0.0" iyy="1.4166666666666668e-07" iyz="0.0" izz="2.6666666666666667e-07"/>
    </inertial>
  </link>
  <link name="r_wrist_link">
    <visual>
      <origin rpy="0 0 0" xyz="0 0 0"/>
      <geometry>
        <cylinder length="0.01" radius="0.02"/>
      </geometry>
      <material name="orbita3d_grey">
        <color rgba="0.8 0.8 0.8 1"/>
      </material>
    </visual>
    <collision>
      <origin rpy="0 0 0" xyz="0 0 0.005"/>
      <geometry>
        <cylinder length="0.01" radius="0.02"/>
      </geometry>
    </collision>
    <inertial>
      <mass value="0.098"/>
      <origin rpy="0 0 0" xyz="0 0 -0.005"/>
      <inertia ixx="1.3883333333333335e-05" ixy="0.0" ixz="0.0" iyy="1.3883333333333335e-05" iyz="0.0" izz="2.6133333333333336e-05"/>
    </inertial>
  </link>
  <link name="r_wrist_ball_link">
    <inertial>
      <origin rpy="0.0 0.0 0.0" xyz="0.0 0.0 0.0"/>
      <mass value="0.001"/>
      <inertia ixx="1.0e-6" ixy="1.0e-8" ixz="1.0e-8" iyy="1.0e-6" iyz="1.0e-8" izz="1.0e-6"/>
    </inertial>
  </link>
  <joint name="r_wrist_ball_joint" type="fixed">
    <origin rpy="0 0 0" xyz="0 0 0"/>
    <parent link="r_wrist_link"/>
    <child link="r_wrist_ball_link"/>
  </joint>
  <link name="r_wrist_base_link">
    <!-- may be used to change reference frame orientation -->
    <inertial>
      <origin rpy="0.0 0.0 0.0" xyz="0.0 0.0 0.0"/>
      <mass value="0.001"/>
      <inertia ixx="1.0e-6" ixy="1.0e-8" ixz="1.0e-8" iyy="1.0e-6" iyz="1.0e-8" izz="1.0e-6"/>
    </inertial>
  </link>
  <joint name="r_wrist_base_joint" type="fixed">
    <!-- inverse frame (z up) -->
    <!-- <origin xyz="${xyz}" rpy="3.141592 0 1.5707963267948966"/> -->
    <!-- do nothing -->
    <origin rpy="3.141592653589793 0 1.5707963267948966" xyz="0 0 0.28"/>
    <parent link="r_elbow_forearm_link"/>
    <child link="r_wrist_base_link"/>
  </joint>
  <link name="r_wrist_out_link">
    <inertial>
      <origin rpy="0.0 0.0 0.0" xyz="0.0 0.0 0.0"/>
      <mass value="0.001"/>
      <inertia ixx="1.0e-6" ixy="1.0e-8" ixz="1.0e-8" iyy="1.0e-6" iyz="1.0e-8" izz="1.0e-6"/>
    </inertial>
  </link>
  <joint name="r_wrist_out_joint" type="fixed">
    <!-- inverse frame (z up) -->
    <origin rpy="3.141592 0 0" xyz="0 0 0"/>
    <!-- do nothing -->
    <!-- <origin xyz="0 0 0" rpy="0 0 0"/> -->
    <parent link="r_wrist_ball_link"/>
    <child link="r_wrist_out_link"/>
  </joint>
  <joint name="r_wrist_roll" type="revolute">
    <!-- <origin xyz="${xyz}" rpy="${rpy}"/> -->
    <origin rpy="0 0 0" xyz="0 0 0"/>
    <!-- <parent link="${parent}"/> -->
    <parent link="r_wrist_base_link"/>
    <child link="r_wrist_dummy_link1"/>
    <axis xyz="1 0 0"/>
    <limit effort="1000.0" lower="-0.7853981633974483" upper="0.7853981633974483" velocity="100.0"/>
    <dynamics damping="0.1" friction="0.1"/>
  </joint>
  <joint name="r_wrist_pitch" type="revolute">
    <origin rpy="0 0 0" xyz="0 0 0"/>
    <parent link="r_wrist_dummy_link1"/>
    <child link="r_wrist_dummy_link2"/>
    <axis xyz="0 1 0"/>
    <limit effort="1000.0" lower="-0.7853981633974483" upper="0.7853981633974483" velocity="100.0"/>
    <dynamics damping="0.1" friction="0.1"/>
  </joint>
  <joint name="r_wrist_yaw" type="revolute">
    <origin rpy="0 0 0" xyz="0 0 0"/>
    <parent link="r_wrist_dummy_link2"/>
    <child link="r_wrist_link"/>
    <axis xyz="0 0 1"/>
    <limit effort="1000.0" lower="-1.57" upper="1.57" velocity="100.0"/>
    <dynamics damping="0.1" friction="0.1"/>
  </joint>
  <!-- URDF definition is so stupid we have to do that... -->
  <!-- <material name="gripperblack"> -->
  <!--     <color rgba="0.4 0.4 0.4 1"/> -->
  <!-- </material> -->
  <!-- <material name="gripperwhite"> -->
  <!--     <color rgba="0.9 0.9 0.9 1"/> -->
  <!-- </material> -->
  <!-- <material name="reachy_yellow"> -->
  <!--     <color rgba="0.8 0.8 0.0 1"/> -->
  <!-- </material> -->
  <!-- <material name="reachy_grey"> -->
  <!--     <color rgba="0.8 0.8 0.8 1"/> -->
  <!-- </material> -->
  <!-- <material name="reachy_metal"> -->
  <!--     <color rgba="0.85 0.85 0.85 1.0"/> -->
  <!-- </material> -->
  <!-- <material name="torsoblack"> -->
  <!--     <color rgba="0.5 0.5 0.5 1.0"/> -->
  <!-- </material> -->
  <!-- <material name="eyewhite"> -->
  <!--     <color rgba="1.0 1.0 1.0 1.0"/> -->
  <!-- </material> -->
  <!-- <material name="orbita2dmetal"> -->
  <!--     <color rgba="0.85 0.85 0.85 1.0"/> -->
  <!-- </material> -->
  <!-- <material name="orbita2dgrey"> -->
  <!--     <color rgba="0.8 0.8 0.8 1.0"/> -->
  <!-- </material> -->
  <!-- <material name="orbita3d_yellow"> -->
  <!--     <color rgba="0.8 0.8 0.0 1"/> -->
  <!-- </material> -->
  <!-- <material name="orbita3d_grey"> -->
  <!--     <color rgba="0.8 0.8 0.8 1"/> -->
  <!-- </material> -->
  <!-- <material name="gripperblack"> -->
  <!--     <color rgba="0.4 0.4 0.4 1"/> -->
  <!-- </material> -->
  <!-- <material name="gripperwhite"> -->
  <!--     <color rgba="0.9 0.9 0.9 1"/> -->
  <!-- </material> -->
  <link name="r_hand_palm_link">
    <collision>
      <!-- <origin xyz="0 0 0.04 " rpy="0 0 0"/> -->
      <origin rpy="0 0 0" xyz="0 0 0.0 "/>
      <geometry>
        <!-- <box size="${gripper_radius} ${gripper_radius*2} ${gripper_length/2}"/> -->
        <!-- <box size="0.08 0.12 0.07"/> -->
        <!-- <mesh filename="package://arm_description/meshes/pincette_right_collider.dae" /> -->
        <mesh filename="file:///home/reachy/reachy_ws/install/arm_description/share/arm_description/meshes/pincette_right_collider.dae"/>
      </geometry>
    </collision>
    <visual>
      <origin rpy="0 0 0" xyz="0 0 0"/>
      <geometry>
        <!-- <mesh filename="file://$(find arm_description)/meshes/pincette_right_visual.dae" /> -->
        <mesh filename="file:///home/reachy/reachy_ws/install/arm_description/share/arm_description/meshes/pincette_right_visual.dae"/>
      </geometry>
    </visual>
    <inertial>
      <origin rpy="0 0 0" xyz="0.00883565 0.00950712 0.0451131"/>
      <mass value="0.30798029"/>
      <inertia ixx="0.00021678" ixy="-0.0000329" ixz="-0.00001728" iyx="-0.0000329" iyy="0.00016983" iyz="-0.00001248" izx="-0.00001728" izy="-0.00001248" izz="0.00023455"/>
    </inertial>
  </link>
  <joint name="r_hand_palm" type="fixed">
    <origin rpy="0.0 0 0" xyz="0 0 0"/>
    <parent link="r_wrist_out_link"/>
    <child link="r_hand_palm_link"/>
  </joint>
  <link name="r_hand_virtual_gripper_link">
    <inertial>
      <origin rpy="0.0 0.0 0.0" xyz="0.0 0.0 0.0"/>
      <mass value="0.001"/>
      <inertia ixx="1.0e-6" ixy="1.0e-8" ixz="1.0e-8" iyy="1.0e-6" iyz="1.0e-8" izz="1.0e-6"/>
    </inertial>
  </link>
  <joint name="r_hand_finger" type="revolute">
    <origin rpy="0 0 0" xyz="0.0 0.0 0.070028"/>
    <parent link="r_hand_palm_link"/>
    <child link="r_hand_virtual_gripper_link"/>
    <axis xyz="1 0 0"/>
    <limit effort="100.0" lower="0.0" upper="2.27" velocity="10.0"/>
    <dynamics damping="0.1" friction="0.1"/>
  </joint>
  <link name="r_hand_proximal_link">
    <inertial>
      <origin rpy="0 0 0" xyz="0.00004101 0.002756 0.019654"/>
      <mass value="0.03926395"/>
      <inertia ixx="0.00001937" ixy="0.0" ixz="7e-8" iyx="0.0" iyy="0.00002003" iyz="3.6e-7" izx="7e-8" izy="3.6e-7" izz="0.00000463"/>
    </inertial>
    <collision>
      <!-- <origin xyz="0 0.006 0.03 " rpy="0 0 0"/> -->
      <!-- <geometry> -->
      <!--   <box size="0.031 0.026 0.06"/> -->
      <!-- </geometry> -->
      <origin rpy="0 0 0" xyz="0 0.00 0.0 "/>
      <geometry>
        <!-- <mesh filename="file://$(find arm_description)/meshes/pincette_proximal_collider.dae" /> -->
        <mesh filename="file:///home/reachy/reachy_ws/install/arm_description/share/arm_description/meshes/pincette_proximal_collider.dae"/>
      </geometry>
    </collision>
    <visual>
      <origin rpy="0 0 0" xyz="0 0 0 "/>
      <geometry>
        <!-- <mesh filename="file://$(find arm_description)/meshes/pincette_proximal_visual.dae" /> -->
        <mesh filename="file:///home/reachy/reachy_ws/install/arm_description/share/arm_description/meshes/pincette_proximal_visual.dae"/>
      </geometry>
    </visual>
  </link>
  <link name="r_hand_proximal_mimic_link">
    <inertial>
      <origin rpy="0 0 0" xyz="0.00004101 0.002756 0.019654"/>
      <mass value="0.03926395"/>
      <inertia ixx="0.00001937" ixy="0.0" ixz="7e-8" iyx="0.0" iyy="0.00002003" iyz="3.6e-7" izx="7e-8" izy="3.6e-7" izz="0.00000463"/>
    </inertial>
    <collision>
      <!-- <origin xyz="0 0.006 0.03 " rpy="0 0 0"/> -->
      <origin rpy="0 0 0" xyz="0 0.0 0.0 "/>
      <geometry>
        <!-- <box size="0.031 0.026 0.06"/> -->
        <!-- <mesh filename="file://$(find arm_description)/meshes/pincette_proximal_collider.dae" /> -->
        <mesh filename="file:///home/reachy/reachy_ws/install/arm_description/share/arm_description/meshes/pincette_proximal_collider.dae"/>
      </geometry>
    </collision>
    <visual>
      <origin rpy="0 0 0" xyz="0 0 0 "/>
      <geometry>
        <!-- <mesh filename="file://$(find arm_description)/meshes/pincette_proximal_visual.dae" /> -->
        <mesh filename="file:///home/reachy/reachy_ws/install/arm_description/share/arm_description/meshes/pincette_proximal_visual.dae"/>
      </geometry>
    </visual>
  </link>
  <joint name="r_hand_finger_proximal" type="revolute">
    <origin rpy="0 0 0" xyz="-0.010196 0.03792 0.070028"/>
    <parent link="r_hand_palm_link"/>
    <child link="r_hand_proximal_link"/>
    <axis xyz="1 0 0"/>
    <limit effort="100.0" lower="-0.51" upper="0.554" velocity="10.0"/>
    <mimic joint="r_hand_finger" multiplier="-0.4689" offset="0.554"/>
    <dynamics damping="0.1" friction="0.1"/>
  </joint>
  <joint name="r_hand_finger_proximal_mimic" type="revolute">
    <origin rpy="0 0 3.141592" xyz="-0.010196 -0.03792 0.070028"/>
    <parent link="r_hand_palm_link"/>
    <child link="r_hand_proximal_mimic_link"/>
    <axis xyz="1 0 0"/>
    <limit effort="100.0" lower="-0.51" upper="0.554" velocity="10.0"/>
    <dynamics damping="0.1" friction="0.1"/>
    <mimic joint="r_hand_finger_proximal" multiplier="1" offset="0"/>
    <dynamics damping="0.1" friction="0.1"/>
  </joint>
  <link name="r_hand_distal_link">
    <inertial>
      <origin rpy="0 0 0" xyz="0.00000695 -0.00006402 0.01772685"/>
      <mass value="0.02821091"/>
      <inertia ixx="0.00000683" ixy="0.0" ixz="0.0" iyx="0.0" iyy="0.00000696" iyz="0.00000127" izx="0.0" izy="0.00000127" izz="0.0000028"/>
    </inertial>
    <collision>
      <!-- <origin xyz="0 0.0015 0.023 " rpy="0 0 0"/> -->
      <origin rpy="0 0 0" xyz="0 0.0 0.0 "/>
      <geometry>
        <!-- <box size="0.031 0.026 0.046"/> -->
        <!-- <mesh filename="file://$(find arm_description)/meshes/pincette_distal_collider.dae" /> -->
        <mesh filename="file:///home/reachy/reachy_ws/install/arm_description/share/arm_description/meshes/pincette_distal_collider.dae"/>
      </geometry>
    </collision>
    <visual>
      <origin rpy="0 0 0" xyz="0 0 0 "/>
      <geometry>
        <!-- <mesh filename="file://$(find arm_description)/meshes/pincette_distal.dae" /> -->
        <mesh filename="file:///home/reachy/reachy_ws/install/arm_description/share/arm_description/meshes/pincette_distal.dae"/>
      </geometry>
    </visual>
  </link>
  <joint name="r_hand_finger_distal" type="revolute">
    <origin rpy="0 0 0" xyz="0 0 0.049997"/>
    <parent link="r_hand_proximal_link"/>
    <child link="r_hand_distal_link"/>
    <axis xyz="1 0 0"/>
    <limit effort="100.0" lower="-0.51" upper="0.554" velocity="10.0"/>
    <!-- <mimic joint="${p}_finger_proximal" multiplier="-1" offset="0" /> -->
    <mimic joint="r_hand_finger" multiplier="0.4689" offset="-0.554"/>
    <dynamics damping="0.1" friction="0.1"/>
  </joint>
  <link name="r_hand_distal_mimic_link">
    <inertial>
      <origin rpy="0 0 0" xyz="0.00000695 -0.00006402 0.01772685"/>
      <mass value="0.02821091"/>
      <inertia ixx="0.00000683" ixy="0.0" ixz="0.0" iyx="0.0" iyy="0.00000696" iyz="0.00000127" izx="0.0" izy="0.00000127" izz="0.0000028"/>
    </inertial>
    <collision>
      <!-- <origin xyz="0 0.0015 0.023 " rpy="0 0 0"/> -->
      <origin rpy="0 0 0" xyz="0 0.00 0.0 "/>
      <geometry>
        <!-- <box size="0.031 0.026 0.046"/> -->
        <!-- <mesh filename="file://$(find arm_description)/meshes/pincette_distal_collider.dae" /> -->
        <mesh filename="file:///home/reachy/reachy_ws/install/arm_description/share/arm_description/meshes/pincette_distal_collider.dae"/>
      </geometry>
    </collision>
    <visual>
      <origin rpy="0 0 0" xyz="0 0 0 "/>
      <geometry>
        <!-- <mesh filename="file://$(find arm_description)/meshes/pincette_distal.dae" /> -->
        <mesh filename="file:///home/reachy/reachy_ws/install/arm_description/share/arm_description/meshes/pincette_distal.dae"/>
      </geometry>
    </visual>
  </link>
  <joint name="r_hand_finger_distal_mimic" type="revolute">
    <origin rpy="0 0 0" xyz="0 0 0.049997"/>
    <parent link="r_hand_proximal_mimic_link"/>
    <child link="r_hand_distal_mimic_link"/>
    <axis xyz="1 0 0"/>
    <limit effort="100.0" lower="-0.51" upper="0.554" velocity="10.0"/>
    <!-- <mimic joint="${p}_finger_proximal" multiplier="-1" offset="0" /> -->
    <mimic joint="r_hand_finger" multiplier="0.4689" offset="-0.554"/>
    <dynamics damping="0.1" friction="0.1"/>
  </joint>
  <link name="r_arm_tip">
    <inertial>
      <origin rpy="0.0 0.0 0.0" xyz="0.0 0.0 0.0"/>
      <mass value="0.001"/>
      <inertia ixx="1.0e-6" ixy="1.0e-8" ixz="1.0e-8" iyy="1.0e-6" iyz="1.0e-8" izz="1.0e-6"/>
    </inertial>
  </link>
  <joint name="r_tip_joint" type="fixed">
    <origin rpy="3.141592653589793 0 0" xyz="0 0 0.1"/>
    <parent link="r_hand_palm_link"/>
    <child link="r_arm_tip"/>
  </joint>
  <ros2_control name="r_arm" type="system">
    <hardware>
      <!-- ROS2 generic fake system -->
      <!-- <plugin>fake_components/GenericSystem</plugin> -->
      <!-- Pollen controllers fake system (simulate a little more) -->
      <plugin>arm_system_hwi/ArmSystemHwi</plugin>
      <param name="config_file">/home/reachy/reachy_ws/install/arm_description/share/arm_description/config/fake_arm.yaml</param>
    </hardware>
    <gpio name="r_shoulder">
      <state_interface name="torque">
        <param name="initial_value">0.0</param>
      </state_interface>
      <command_interface name="torque"/>
    </gpio>
    <joint name="r_shoulder_pitch">
      <state_interface name="position">
        <param name="initial_value">0.0</param>
      </state_interface>
      <state_interface name="velocity">
        <param name="initial_value">0.0</param>
      </state_interface>
      <state_interface name="effort">
        <param name="initial_value">0.0</param>
      </state_interface>
      <command_interface name="position"/>
    </joint>
    <joint name="r_shoulder_roll">
      <state_interface name="position">
        <param name="initial_value">0.0</param>
      </state_interface>
      <state_interface name="velocity">
        <param name="initial_value">0.0</param>
      </state_interface>
      <state_interface name="effort">
        <param name="initial_value">0.0</param>
      </state_interface>
      <command_interface name="position"/>
    </joint>
    <gpio name="r_shoulder_raw_motor_1">
      <state_interface name="speed_limit"/>
      <command_interface name="speed_limit"/>
      <state_interface name="torque_limit"/>
      <command_interface name="torque_limit"/>
      <state_interface name="p_gain"/>
      <command_interface name="p_gain"/>
      <state_interface name="i_gain"/>
      <command_interface name="i_gain"/>
      <state_interface name="d_gain"/>
      <command_interface name="d_gain"/>
    </gpio>
    <gpio name="r_shoulder_raw_motor_2">
      <state_interface name="speed_limit"/>
      <command_interface name="speed_limit"/>
      <state_interface name="torque_limit"/>
      <command_interface name="torque_limit"/>
      <state_interface name="p_gain"/>
      <command_interface name="p_gain"/>
      <state_interface name="i_gain"/>
      <command_interface name="i_gain"/>
      <state_interface name="d_gain"/>
      <command_interface name="d_gain"/>
    </gpio>
    <gpio name="r_elbow">
      <state_interface name="torque">
        <param name="initial_value">0.0</param>
      </state_interface>
      <command_interface name="torque"/>
    </gpio>
    <joint name="r_elbow_yaw">
      <state_interface name="position">
        <param name="initial_value">0.0</param>
      </state_interface>
      <state_interface name="velocity">
        <param name="initial_value">0.0</param>
      </state_interface>
      <state_interface name="effort">
        <param name="initial_value">0.0</param>
      </state_interface>
      <command_interface name="position"/>
    </joint>
    <joint name="r_elbow_pitch">
      <state_interface name="position">
        <param name="initial_value">0.0</param>
      </state_interface>
      <state_interface name="velocity">
        <param name="initial_value">0.0</param>
      </state_interface>
      <state_interface name="effort">
        <param name="initial_value">0.0</param>
      </state_interface>
      <command_interface name="position"/>
    </joint>
    <gpio name="r_elbow_raw_motor_1">
      <state_interface name="speed_limit"/>
      <command_interface name="speed_limit"/>
      <state_interface name="torque_limit"/>
      <command_interface name="torque_limit"/>
      <state_interface name="p_gain"/>
      <command_interface name="p_gain"/>
      <state_interface name="i_gain"/>
      <command_interface name="i_gain"/>
      <state_interface name="d_gain"/>
      <command_interface name="d_gain"/>
    </gpio>
    <gpio name="r_elbow_raw_motor_2">
      <state_interface name="speed_limit"/>
      <command_interface name="speed_limit"/>
      <state_interface name="torque_limit"/>
      <command_interface name="torque_limit"/>
      <state_interface name="p_gain"/>
      <command_interface name="p_gain"/>
      <state_interface name="i_gain"/>
      <command_interface name="i_gain"/>
      <state_interface name="d_gain"/>
      <command_interface name="d_gain"/>
    </gpio>
    <gpio name="r_wrist">
      <state_interface name="torque">
        <param name="initial_value">0.0</param>
      </state_interface>
      <command_interface name="torque"/>
    </gpio>
    <joint name="r_wrist_roll">
      <state_interface name="position">
        <param name="initial_value">0.0</param>
      </state_interface>
      <state_interface name="velocity">
        <param name="initial_value">0.0</param>
      </state_interface>
      <state_interface name="effort">
        <param name="initial_value">0.0</param>
      </state_interface>
      <command_interface name="position"/>
    </joint>
    <joint name="r_wrist_pitch">
      <state_interface name="position">
        <param name="initial_value">0.0</param>
      </state_interface>
      <state_interface name="velocity">
        <param name="initial_value">0.0</param>
      </state_interface>
      <state_interface name="effort">
        <param name="initial_value">0.0</param>
      </state_interface>
      <command_interface name="position"/>
    </joint>
    <joint name="r_wrist_yaw">
      <state_interface name="position">
        <param name="initial_value">0.0</param>
      </state_interface>
      <state_interface name="velocity">
        <param name="initial_value">0.0</param>
      </state_interface>
      <state_interface name="effort">
        <param name="initial_value">0.0</param>
      </state_interface>
      <command_interface name="position"/>
    </joint>
    <gpio name="r_wrist_raw_motor_1">
      <state_interface name="speed_limit"/>
      <command_interface name="speed_limit"/>
      <state_interface name="torque_limit"/>
      <command_interface name="torque_limit"/>
      <state_interface name="p_gain"/>
      <command_interface name="p_gain"/>
      <state_interface name="i_gain"/>
      <command_interface name="i_gain"/>
      <state_interface name="d_gain"/>
      <command_interface name="d_gain"/>
    </gpio>
    <gpio name="r_wrist_raw_motor_2">
      <state_interface name="speed_limit"/>
      <command_interface name="speed_limit"/>
      <state_interface name="torque_limit"/>
      <command_interface name="torque_limit"/>
      <state_interface name="p_gain"/>
      <command_interface name="p_gain"/>
      <state_interface name="i_gain"/>
      <command_interface name="i_gain"/>
      <state_interface name="d_gain"/>
      <command_interface name="d_gain"/>
    </gpio>
    <gpio name="r_wrist_raw_motor_3">
      <state_interface name="speed_limit"/>
      <command_interface name="speed_limit"/>
      <state_interface name="torque_limit"/>
      <command_interface name="torque_limit"/>
      <state_interface name="p_gain"/>
      <command_interface name="p_gain"/>
      <state_interface name="i_gain"/>
      <command_interface name="i_gain"/>
      <state_interface name="d_gain"/>
      <command_interface name="d_gain"/>
    </gpio>
    <gpio name="r_hand">
      <state_interface name="torque">
        <param name="initial_value">0.0</param>
      </state_interface>
      <command_interface name="torque"/>
    </gpio>
    <joint name="r_hand_finger">
      <state_interface name="position">
        <param name="initial_value">0.0</param>
      </state_interface>
      <state_interface name="velocity">
        <param name="initial_value">0.0</param>
      </state_interface>
      <state_interface name="effort">
        <param name="initial_value">0.0</param>
      </state_interface>
      <command_interface name="position"/>
    </joint>
    <gpio name="r_hand_raw_motor_1">
      <state_interface name="speed_limit"/>
      <command_interface name="speed_limit"/>
      <state_interface name="torque_limit"/>
      <command_interface name="torque_limit"/>
      <state_interface name="p_gain"/>
      <command_interface name="p_gain"/>
      <state_interface name="i_gain"/>
      <command_interface name="i_gain"/>
      <state_interface name="d_gain"/>
      <command_interface name="d_gain"/>
    </gpio>
  </ros2_control>
  <!-- URDF definition is so stupid we have to do that... -->
  <!-- <material name="gripperblack"> -->
  <!--     <color rgba="0.4 0.4 0.4 1"/> -->
  <!-- </material> -->
  <!-- <material name="gripperwhite"> -->
  <!--     <color rgba="0.9 0.9 0.9 1"/> -->
  <!-- </material> -->
  <!-- <material name="reachy_yellow"> -->
  <!--     <color rgba="0.8 0.8 0.0 1"/> -->
  <!-- </material> -->
  <!-- <material name="reachy_grey"> -->
  <!--     <color rgba="0.8 0.8 0.8 1"/> -->
  <!-- </material> -->
  <!-- <material name="reachy_metal"> -->
  <!--     <color rgba="0.85 0.85 0.85 1.0"/> -->
  <!-- </material> -->
  <!-- <material name="torsoblack"> -->
  <!--     <color rgba="0.5 0.5 0.5 1.0"/> -->
  <!-- </material> -->
  <!-- <material name="eyewhite"> -->
  <!--     <color rgba="1.0 1.0 1.0 1.0"/> -->
  <!-- </material> -->
  <!-- <material name="orbita2dmetal"> -->
  <!--     <color rgba="0.85 0.85 0.85 1.0"/> -->
  <!-- </material> -->
  <!-- <material name="orbita2dgrey"> -->
  <!--     <color rgba="0.8 0.8 0.8 1.0"/> -->
  <!-- </material> -->
  <!-- <material name="orbita3d_yellow"> -->
  <!--     <color rgba="0.8 0.8 0.0 1"/> -->
  <!-- </material> -->
  <!-- <material name="orbita3d_grey"> -->
  <!--     <color rgba="0.8 0.8 0.8 1"/> -->
  <!-- </material> -->
  <!-- URDF definition is so stupid we have to do that... -->
  <!-- <material name="gripperblack"> -->
  <!--     <color rgba="0.4 0.4 0.4 1"/> -->
  <!-- </material> -->
  <!-- <material name="gripperwhite"> -->
  <!--     <color rgba="0.9 0.9 0.9 1"/> -->
  <!-- </material> -->
  <!-- <material name="reachy_yellow"> -->
  <!--     <color rgba="0.8 0.8 0.0 1"/> -->
  <!-- </material> -->
  <!-- <material name="reachy_grey"> -->
  <!--     <color rgba="0.8 0.8 0.8 1"/> -->
  <!-- </material> -->
  <!-- <material name="reachy_metal"> -->
  <!--     <color rgba="0.85 0.85 0.85 1.0"/> -->
  <!-- </material> -->
  <!-- <material name="torsoblack"> -->
  <!--     <color rgba="0.5 0.5 0.5 1.0"/> -->
  <!-- </material> -->
  <!-- <material name="eyewhite"> -->
  <!--     <color rgba="1.0 1.0 1.0 1.0"/> -->
  <!-- </material> -->
  <!-- <material name="orbita2dmetal"> -->
  <!--     <color rgba="0.85 0.85 0.85 1.0"/> -->
  <!-- </material> -->
  <!-- <material name="orbita2dgrey"> -->
  <!--     <color rgba="0.8 0.8 0.8 1.0"/> -->
  <!-- </material> -->
  <!-- <material name="orbita3d_yellow"> -->
  <!--     <color rgba="0.8 0.8 0.0 1"/> -->
  <!-- </material> -->
  <!-- <material name="orbita3d_grey"> -->
  <!--     <color rgba="0.8 0.8 0.8 1"/> -->
  <!-- </material> -->
  <!-- <!-\- Orbita2d config -\-> -->
  <!-- <xacro:arg name="orbita2d_shoulder_config" default="$(find
    orbita2d_description)/config/fake.yaml"/> -->
  <!-- <xacro:arg name="orbita2d_elbow_config" default="$(find
    orbita2d_description)/config/fake.yaml"/> -->
  <!-- <!-\- Orbita3d config -\-> -->
  <!-- <xacro:arg name="orbita3d_wrist_config" default="$(find
    orbita3d_controller)/config/fake.yaml"/> -->
  <!-- ARM PARAMETERS -->
  <link name="l_shoulder_base_link">
    <inertial>
      <origin rpy="0.0 0.0 0.0" xyz="0.0 0.0 0.0"/>
      <mass value="0.001"/>
      <inertia ixx="1.0e-6" ixy="1.0e-8" ixz="1.0e-8" iyy="1.0e-6" iyz="1.0e-8" izz="1.0e-6"/>
    </inertial>
  </link>
  <joint name="l_shoulder_base_joint" type="fixed">
    <!-- <origin xyz="${arm_offset_x} ${arm_offset_y*reflect} ${arm_offset_z}" rpy="${(1.5707963267948966+(virtual_shoulder_roll_offset - arm_offset_roll))*reflect} 0 ${arm_offset_yaw*reflect}" /> -->
    <origin rpy="-1.3089969389957472 0 -0.17453292519943295" xyz="0.0 0.2 0.0"/>
    <parent link="torso"/>
    <child link="l_shoulder_base_link"/>
  </joint>
  <!--
      Orbita 2 dof

    link                         (joint)

    ${parent}                    (${name}_dummy_1) fixed
      ${name}_dummy_link1        (${name}_dummy_2) fixed
        ${name}_dummy_link2      (${name}_joint1) revolute
          ${name}_first_link     (${name}_joint2) revolute
      	    ${name}_ball_link    (${name}_dummy_out) fixed
	      ${name}_fix_link


    -->
  <!-- used to "place" the joint with the correct axis. For some reason rotation of the inertia matrix does not work... -->
  <link name="l_shoulder_dummy_link1">
    <inertial>
      <origin rpy="0.0 0.0 0.0" xyz="0.0 0.0 0.0"/>
      <mass value="0.001"/>
      <inertia ixx="1.0e-6" ixy="1.0e-8" ixz="1.0e-8" iyy="1.0e-6" iyz="1.0e-8" izz="1.0e-6"/>
    </inertial>
  </link>
  <joint name="l_shoulder_dummy_1" type="fixed">
    <origin rpy="0 0 0" xyz="0 0 0"/>
    <parent link="l_shoulder_base_link"/>
    <child link="l_shoulder_dummy_link1"/>
  </joint>
  <link name="l_shoulder_dummy_link2">
    <inertial>
      <origin rpy="0.0 0.0 0.0" xyz="0.0 0.0 0.0"/>
      <mass value="0.001"/>
      <inertia ixx="1.0e-6" ixy="1.0e-8" ixz="1.0e-8" iyy="1.0e-6" iyz="1.0e-8" izz="1.0e-6"/>
    </inertial>
  </link>
  <!-- used to rotatate the joint to respect the conventional axis -->
  <joint name="l_shoulder_dummy_2" type="fixed">
    <origin rpy="1.5707963267948966 0 0" xyz="0 0 0"/>
    <!-- <origin xyz="0 0 0" rpy="0 0 0"/> -->
    <parent link="l_shoulder_dummy_link1"/>
    <child link="l_shoulder_dummy_link2"/>
  </joint>
  <link name="l_shoulder_first_link">
    <visual>
      <origin rpy="-1.5707963267948966 0 0" xyz="0 0 0"/>
      <geometry>
        <!-- <mesh filename="file://$(find arm_description)/meshes/Orbita2D_ball.dae" /> -->
        <mesh filename="file:///home/reachy/reachy_ws/install/arm_description/share/arm_description/meshes/2D_sphere_visual.dae"/>
      </geometry>
    </visual>
    <!-- <collision> -->
    <!--   <geometry> -->
    <!--     <sphere radius="0.0425"/> -->
    <!--   </geometry> -->
    <!-- </collision> -->
    <inertial>
      <!-- <origin xyz="0.0 0 0" rpy="1.5707963267948966 0 0"/> -->
      <!-- rotation does not work? -->
      <origin rpy="0 0 0" xyz="0.000096 -0.000015 -0.01777"/>
      <mass value="0.487"/>
      <inertia ixx="0.000577881945" ixy="-8.085000000000001e-7" ixz="-6.962790000000001e-7" iyx="-8.085000000000001e-7" iyy="0.000573075516" iyz="2.44386e-7" izx="-6.962790000000001e-7" izy="2.44386e-7" izz="0.000243343676"/>
    </inertial>
  </link>
  <!-- First joint  -->
  <joint name="l_shoulder_pitch" type="revolute">
    <origin rpy="0 0 0" xyz="0 0 0"/>
    <!-- <parent link="${parent}"/> -->
    <parent link="l_shoulder_dummy_link2"/>
    <child link="l_shoulder_first_link"/>
    <axis xyz="0 1 0"/>
    <!-- <axis xyz="0 0 -1"/> -->
    <limit effort="1000.0" lower="-1.5707963267948966" upper="1.5707963267948966" velocity="100.0"/>
    <safety_controller k_position="500" k_velocity="500" soft_lower_limit="-3.141592" soft_upper_limit="3.1415"/>
    <dynamics damping="0.1" friction="0.1"/>
  </joint>
  <!-- <!-\- Used to get back to the correct orientation -\-> -->
  <!-- <link name="${name}_dummy_link3"> -->
  <!-- </link> -->
  <!-- <joint name="${name}_dummy_3" type="fixed"> -->
  <!--   <!-\- <origin xyz="0 0 0" rpy="-1.5707963267948966 0 0"/> -\-> -->
  <!--   <origin xyz="0 0 0" rpy="3.141592653589793 0 0"/> -->
  <!--   <parent link="${name}_first_link"/> -->
  <!--   <child link="${name}_dummy_link3"/> -->
  <!-- </joint> -->
  <!-- Output link -->
  <link name="l_shoulder_ball_link">
    <inertial>
      <origin rpy="0.0 0.0 0.0" xyz="0.0 0.0 0.0"/>
      <mass value="0.001"/>
      <inertia ixx="1.0e-6" ixy="1.0e-8" ixz="1.0e-8" iyy="1.0e-6" iyz="1.0e-8" izz="1.0e-6"/>
    </inertial>
  </link>
  <joint name="l_shoulder_roll" type="revolute">
    <origin rpy=" 0 0 0" xyz="0 0 0"/>
    <parent link="l_shoulder_first_link"/>
    <child link="l_shoulder_ball_link"/>
    <axis xyz="1 0 0"/>
    <!-- <axis xyz="1 0 0"/> -->
    <limit effort="1000.0" lower="-0.0" upper="1.5707963267948966" velocity="100.0"/>
    <safety_controller k_position="500" k_velocity="500" soft_lower_limit="-3.1415" soft_upper_limit="3.1415"/>
    <dynamics damping="0.1" friction="0.1"/>
  </joint>
  <link name="l_shoulder_fix_link">
    <inertial>
      <origin rpy="0.0 0.0 0.0" xyz="0.0 0.0 0.0"/>
      <mass value="0.001"/>
      <inertia ixx="1.0e-6" ixy="1.0e-8" ixz="1.0e-8" iyy="1.0e-6" iyz="1.0e-8" izz="1.0e-6"/>
    </inertial>
  </link>
  <!-- used to rotate the joint to respect the conventional axis -->
  <joint name="l_shoulder_dummy_out" type="fixed">
    <origin rpy="1.5707963267948966 0 0" xyz="0 0 0"/>
    <!-- <origin xyz="0 0 0" rpy="0 0 0"/> -->
    <parent link="l_shoulder_ball_link"/>
    <child link="l_shoulder_fix_link"/>
  </joint>
  <!-- <xacro:orbita2d_control -->
  <!--   name="${name}" -->
  <!--   joint1="${joint1}" joint2="${joint2}" -->
  <!--   config_file="${config_file}" -->
  <!-- /> -->
  <link name="l_elbow_arm_link">
    <visual>
      <origin rpy="0 0 0" xyz="0 0 0"/>
      <geometry>
        <!-- <mesh filename="package://arm_description/meshes/upper_arm_visual.dae" /> -->
        <mesh filename="file:///home/reachy/reachy_ws/install/arm_description/share/arm_description/meshes/upper_arm_visual.dae"/>
      </geometry>
    </visual>
    <collision>
      <!-- <origin xyz="0 0 ${arm_length/2}" rpy="0 0 0"/> -->
      <origin rpy="0 0 0" xyz="0 0 0"/>
      <geometry>
        <!-- <mesh filename="package://arm_description/meshes/upper_arm_collider.dae" /> -->
        <mesh filename="file:///home/reachy/reachy_ws/install/arm_description/share/arm_description/meshes/upper_arm_collider.dae"/>
      </geometry>
    </collision>
    <inertial>
      <origin rpy="0 0 0" xyz="-0.000669 0.000509 0.144798"/>
      <mass value="1.620"/>
      <inertia ixx="0.007864" ixy="0.000005410021" ixz="-0.000117782969" iyx="0.000005410021" iyy="0.006998" iyz="0.000121931452" izx="-0.000117782969" izy="0.000121931452" izz="0.001828"/>
    </inertial>
  </link>
  <joint name="l_elbow_arm_joint" type="fixed">
    <origin rpy="0 -1.5707963267948966 1.5707963267948966" xyz="0 0 0.0"/>
    <!-- <origin xyz="0 0 0.0" rpy="0 0 0" /> -->
    <!-- <parent link="${p}_shoulder_ball_link" /> -->
    <parent link="l_shoulder_fix_link"/>
    <child link="l_elbow_arm_link"/>
  </joint>
  <link name="l_elbow_base_link">
    <inertial>
      <origin rpy="0.0 0.0 0.0" xyz="0.0 0.0 0.0"/>
      <mass value="0.001"/>
      <inertia ixx="1.0e-6" ixy="1.0e-8" ixz="1.0e-8" iyy="1.0e-6" iyz="1.0e-8" izz="1.0e-6"/>
    </inertial>
  </link>
  <!-- <joint name="${prefix}_elbow_base_joint" type="fixed"> -->
  <!--   <origin xyz="0 0 0" rpy="0 ${(1.5707963267948966 + virtual_elbow_offset_yaw)*reflect} 0" /> -->
  <!--   <parent link="${p}_shoulder_ball_link" /> -->
  <!--   <child link="${prefix}_elbow_base_link" /> -->
  <!-- </joint> -->
  <!-- <xacro:orbita2d -->
  <!--   name="${p}_elbow" parent="${prefix}_elbow_base_link" -->
  <!--   length="${forearm_length}" radius="${forearm_radius}" mass="${forearm_mass}" -->
  <!--   xyz="0 -${arm_length} 0" rpy="${1.5707963267948966} 0 0" -->
  <!--   damping="${damping}" friction="${friction}" -->
  <!--   joint1="yaw" joint2="pitch" -->
  <!--   joint1_min_angle="-${pi/2}" joint1_max_angle="${pi/2}" -->
  <!--   joint2_min_angle="-2.25" joint2_max_angle="0.1" -->
  <!-- /> -->
  <joint name="l_elbow_base_joint" type="fixed">
    <origin rpy="0 0 0" xyz="0 0 0.28"/>
    <parent link="l_elbow_arm_link"/>
    <child link="l_elbow_base_link"/>
  </joint>
  <!--
      Orbita 2 dof

    link                         (joint)

    ${parent}                    (${name}_dummy_1) fixed
      ${name}_dummy_link1        (${name}_dummy_2) fixed
        ${name}_dummy_link2      (${name}_joint1) revolute
          ${name}_first_link     (${name}_joint2) revolute
      	    ${name}_ball_link    (${name}_dummy_out) fixed
	      ${name}_fix_link


    -->
  <!-- used to "place" the joint with the correct axis. For some reason rotation of the inertia matrix does not work... -->
  <link name="l_elbow_dummy_link1">
    <inertial>
      <origin rpy="0.0 0.0 0.0" xyz="0.0 0.0 0.0"/>
      <mass value="0.001"/>
      <inertia ixx="1.0e-6" ixy="1.0e-8" ixz="1.0e-8" iyy="1.0e-6" iyz="1.0e-8" izz="1.0e-6"/>
    </inertial>
  </link>
  <joint name="l_elbow_dummy_1" type="fixed">
    <origin rpy="0 0 0" xyz="0 0 0"/>
    <parent link="l_elbow_base_link"/>
    <child link="l_elbow_dummy_link1"/>
  </joint>
  <link name="l_elbow_dummy_link2">
    <inertial>
      <origin rpy="0.0 0.0 0.0" xyz="0.0 0.0 0.0"/>
      <mass value="0.001"/>
      <inertia ixx="1.0e-6" ixy="1.0e-8" ixz="1.0e-8" iyy="1.0e-6" iyz="1.0e-8" izz="1.0e-6"/>
    </inertial>
  </link>
  <!-- used to rotatate the joint to respect the conventional axis -->
  <joint name="l_elbow_dummy_2" type="fixed">
    <origin rpy="3.141592 0 -1.5707963267948966" xyz="0 0 0"/>
    <!-- <origin xyz="0 0 0" rpy="0 0 0"/> -->
    <parent link="l_elbow_dummy_link1"/>
    <child link="l_elbow_dummy_link2"/>
  </joint>
  <link name="l_elbow_first_link">
    <visual>
      <origin rpy="3.141592 0 1.5707963267948966" xyz="0 0 0"/>
      <geometry>
        <!-- <mesh filename="file://$(find arm_description)/meshes/Orbita2D_ball.dae" /> -->
        <mesh filename="file:///home/reachy/reachy_ws/install/arm_description/share/arm_description/meshes/2D_sphere_visual.dae"/>
      </geometry>
    </visual>
    <!-- <collision> -->
    <!--   <geometry> -->
    <!--     <sphere radius="0.0425"/> -->
    <!--   </geometry> -->
    <!-- </collision> -->
    <inertial>
      <!-- <origin xyz="0.0 0 0" rpy="1.5707963267948966 0 0"/> -->
      <!-- rotation does not work? -->
      <origin rpy="0 0 0" xyz="0.000096 -0.000015 -0.01777"/>
      <mass value="0.487"/>
      <inertia ixx="0.000577881945" ixy="-8.085000000000001e-7" ixz="-6.962790000000001e-7" iyx="-8.085000000000001e-7" iyy="0.000573075516" iyz="2.44386e-7" izx="-6.962790000000001e-7" izy="2.44386e-7" izz="0.000243343676"/>
    </inertial>
  </link>
  <!-- First joint  -->
  <joint name="l_elbow_yaw" type="revolute">
    <origin rpy="0 0 0" xyz="0 0 0"/>
    <!-- <parent link="${parent}"/> -->
    <parent link="l_elbow_dummy_link2"/>
    <child link="l_elbow_first_link"/>
    <axis xyz="0 0 1"/>
    <!-- <axis xyz="0 0 -1"/> -->
    <limit effort="1000.0" lower="-1.5707963267948966" upper="1.5707963267948966" velocity="100.0"/>
    <safety_controller k_position="500" k_velocity="500" soft_lower_limit="-3.141592" soft_upper_limit="3.1415"/>
    <dynamics damping="0.1" friction="0.1"/>
  </joint>
  <!-- <!-\- Used to get back to the correct orientation -\-> -->
  <!-- <link name="${name}_dummy_link3"> -->
  <!-- </link> -->
  <!-- <joint name="${name}_dummy_3" type="fixed"> -->
  <!--   <!-\- <origin xyz="0 0 0" rpy="-1.5707963267948966 0 0"/> -\-> -->
  <!--   <origin xyz="0 0 0" rpy="3.141592653589793 0 0"/> -->
  <!--   <parent link="${name}_first_link"/> -->
  <!--   <child link="${name}_dummy_link3"/> -->
  <!-- </joint> -->
  <!-- Output link -->
  <link name="l_elbow_ball_link">
    <inertial>
      <origin rpy="0.0 0.0 0.0" xyz="0.0 0.0 0.0"/>
      <mass value="0.001"/>
      <inertia ixx="1.0e-6" ixy="1.0e-8" ixz="1.0e-8" iyy="1.0e-6" iyz="1.0e-8" izz="1.0e-6"/>
    </inertial>
  </link>
  <joint name="l_elbow_pitch" type="revolute">
    <origin rpy=" 0 0 0" xyz="0 0 0"/>
    <parent link="l_elbow_first_link"/>
    <child link="l_elbow_ball_link"/>
    <axis xyz="0 1 0"/>
    <!-- <axis xyz="1 0 0"/> -->
    <limit effort="1000.0" lower="-2.25" upper="0.1" velocity="100.0"/>
    <safety_controller k_position="500" k_velocity="500" soft_lower_limit="-3.1415" soft_upper_limit="3.1415"/>
    <dynamics damping="0.1" friction="0.1"/>
  </joint>
  <link name="l_elbow_fix_link">
    <inertial>
      <origin rpy="0.0 0.0 0.0" xyz="0.0 0.0 0.0"/>
      <mass value="0.001"/>
      <inertia ixx="1.0e-6" ixy="1.0e-8" ixz="1.0e-8" iyy="1.0e-6" iyz="1.0e-8" izz="1.0e-6"/>
    </inertial>
  </link>
  <!-- used to rotate the joint to respect the conventional axis -->
  <joint name="l_elbow_dummy_out" type="fixed">
    <origin rpy="3.141592 0 1.5707963267948966" xyz="0 0 0"/>
    <!-- <origin xyz="0 0 0" rpy="0 0 0"/> -->
    <parent link="l_elbow_ball_link"/>
    <child link="l_elbow_fix_link"/>
  </joint>
  <!-- <xacro:orbita2d_control -->
  <!--   name="${name}" -->
  <!--   joint1="${joint1}" joint2="${joint2}" -->
  <!--   config_file="${config_file}" -->
  <!-- /> -->
  <!-- <link name="${prefix}_elbow_forearm_link"> -->
  <!--   <visual> -->
  <!--   	<origin xyz="0 0 0" rpy="0 0 0"/> -->
  <!--   	<geometry> -->
  <!-- 	  <mesh filename="package://arm_description/meshes/Orbita2D_forearm.dae" /> -->
  <!--   	</geometry> -->
  <!--   </visual> -->
  <!--   <inertial> -->
  <!--   	<origin xyz="0.00092892 -0.00254548 0.14021211" rpy="0 0 0"/> -->
  <!-- 	<mass value="0.90719109"/> -->
  <!-- 	 <inertia ixx="0.00428278" ixy="-0.00000203" ixz="0.00011755" -->
  <!-- 		  iyx="-0.00000203" iyy="0.0044585" iyz="-0.00004915" -->
  <!-- 		  izx="0.00011755" izy="-0.00004915" izz="0.00047615"/> -->
  <!--   </inertial> -->
  <!-- </link> -->
  <!-- <joint name="${prefix}_elbow_forearm_joint" type="fixed"> -->
  <!--   <origin xyz="0 0 0.0" rpy="0 0 0" /> -->
  <!--   <parent link="${p}_elbow_ball_link" /> -->
  <!--   <child link="${prefix}_elbow_forearm_link" /> -->
  <!-- </joint> -->
  <link name="l_elbow_forearm_link">
    <visual>
      <origin rpy="0 0 0" xyz="0 0 0"/>
      <geometry>
        <!-- <mesh filename="package://arm_description/meshes/forearm_visual.dae" /> -->
        <mesh filename="file:///home/reachy/reachy_ws/install/arm_description/share/arm_description/meshes/forearm_visual.dae"/>
      </geometry>
    </visual>
    <collision>
      <origin rpy="0 0 0" xyz="0 0 0"/>
      <!-- <origin xyz="0 0 ${forearm_length/2}" rpy="0 0 0"/> -->
      <geometry>
        <!-- <mesh filename="package://arm_description/meshes/forearm_collider.dae" /> -->
        <mesh filename="file:///home/reachy/reachy_ws/install/arm_description/share/arm_description/meshes/forearm_collider.dae"/>
      </geometry>
    </collision>
    <inertial>
      <origin rpy="0 0 0" xyz="0.00092892 -0.00254548 0.14021211"/>
      <mass value="0.90719109"/>
      <inertia ixx="0.00428278" ixy="-0.00000203" ixz="0.00011755" iyx="-0.00000203" iyy="0.0044585" iyz="-0.00004915" izx="0.00011755" izy="-0.00004915" izz="0.00047615"/>
    </inertial>
  </link>
  <joint name="l_elbow_forearm_joint" type="fixed">
    <origin rpy="0 0 0" xyz="0 0 0.0"/>
    <!-- <parent link="${p}_elbow_ball_link" /> -->
    <parent link="l_elbow_fix_link"/>
    <child link="l_elbow_forearm_link"/>
  </joint>
  <!-- <xacro:orbita3d -->
  <!--   name="${p}_wrist" parent="${p}_elbow_ball_link" -->
  <!--   length="${wrist_length}" radius="${wrist_radius}" mass="${wrist_mass}" -->
  <!--   xyz="0 0 ${forearm_length}" rpy="${pi} 0 0" -->
  <!--   damping="${damping}" friction="${friction}" -->
  <!-- /> -->
  <!--
      Orbita3d

    link                         (joint)

    ${parent}                    (${name}_base_joint) fixed
      ${name}_base_link          (${name}_roll) revolute
        ${name}_dummy_link1      (${name}_pitch) revolute
          ${name}_dummy_link2    (${name}_yaw) revolute
            ${name}_link         (${name}_ball_joint) fixed
              ${name}_ball_link
    -->
  <link name="l_wrist_dummy_link1">
    <inertial>
      <mass value="0.001"/>
      <origin rpy="0 0 0" xyz="0 0 0"/>
      <inertia ixx="1.4166666666666668e-07" ixy="0.0" ixz="0.0" iyy="1.4166666666666668e-07" iyz="0.0" izz="2.6666666666666667e-07"/>
    </inertial>
  </link>
  <link name="l_wrist_dummy_link2">
    <inertial>
      <mass value="0.001"/>
      <origin rpy="0 0 0" xyz="0 0 0"/>
      <inertia ixx="1.4166666666666668e-07" ixy="0.0" ixz="0.0" iyy="1.4166666666666668e-07" iyz="0.0" izz="2.6666666666666667e-07"/>
    </inertial>
  </link>
  <link name="l_wrist_link">
    <visual>
      <origin rpy="0 0 0" xyz="0 0 0"/>
      <geometry>
        <cylinder length="0.01" radius="0.02"/>
      </geometry>
      <material name="orbita3d_grey">
        <color rgba="0.8 0.8 0.8 1"/>
      </material>
    </visual>
    <collision>
      <origin rpy="0 0 0" xyz="0 0 0.005"/>
      <geometry>
        <cylinder length="0.01" radius="0.02"/>
      </geometry>
    </collision>
    <inertial>
      <mass value="0.098"/>
      <origin rpy="0 0 0" xyz="0 0 -0.005"/>
      <inertia ixx="1.3883333333333335e-05" ixy="0.0" ixz="0.0" iyy="1.3883333333333335e-05" iyz="0.0" izz="2.6133333333333336e-05"/>
    </inertial>
  </link>
  <link name="l_wrist_ball_link">
    <inertial>
      <origin rpy="0.0 0.0 0.0" xyz="0.0 0.0 0.0"/>
      <mass value="0.001"/>
      <inertia ixx="1.0e-6" ixy="1.0e-8" ixz="1.0e-8" iyy="1.0e-6" iyz="1.0e-8" izz="1.0e-6"/>
    </inertial>
  </link>
  <joint name="l_wrist_ball_joint" type="fixed">
    <origin rpy="0 0 0" xyz="0 0 0"/>
    <parent link="l_wrist_link"/>
    <child link="l_wrist_ball_link"/>
  </joint>
  <link name="l_wrist_base_link">
    <!-- may be used to change reference frame orientation -->
    <inertial>
      <origin rpy="0.0 0.0 0.0" xyz="0.0 0.0 0.0"/>
      <mass value="0.001"/>
      <inertia ixx="1.0e-6" ixy="1.0e-8" ixz="1.0e-8" iyy="1.0e-6" iyz="1.0e-8" izz="1.0e-6"/>
    </inertial>
  </link>
  <joint name="l_wrist_base_joint" type="fixed">
    <!-- inverse frame (z up) -->
    <!-- <origin xyz="${xyz}" rpy="3.141592 0 1.5707963267948966"/> -->
    <!-- do nothing -->
    <origin rpy="3.141592653589793 0 1.5707963267948966" xyz="0 0 0.28"/>
    <parent link="l_elbow_forearm_link"/>
    <child link="l_wrist_base_link"/>
  </joint>
  <link name="l_wrist_out_link">
    <inertial>
      <origin rpy="0.0 0.0 0.0" xyz="0.0 0.0 0.0"/>
      <mass value="0.001"/>
      <inertia ixx="1.0e-6" ixy="1.0e-8" ixz="1.0e-8" iyy="1.0e-6" iyz="1.0e-8" izz="1.0e-6"/>
    </inertial>
  </link>
  <joint name="l_wrist_out_joint" type="fixed">
    <!-- inverse frame (z up) -->
    <origin rpy="3.141592 0 0" xyz="0 0 0"/>
    <!-- do nothing -->
    <!-- <origin xyz="0 0 0" rpy="0 0 0"/> -->
    <parent link="l_wrist_ball_link"/>
    <child link="l_wrist_out_link"/>
  </joint>
  <joint name="l_wrist_roll" type="revolute">
    <!-- <origin xyz="${xyz}" rpy="${rpy}"/> -->
    <origin rpy="0 0 0" xyz="0 0 0"/>
    <!-- <parent link="${parent}"/> -->
    <parent link="l_wrist_base_link"/>
    <child link="l_wrist_dummy_link1"/>
    <axis xyz="1 0 0"/>
    <limit effort="1000.0" lower="-0.7853981633974483" upper="0.7853981633974483" velocity="100.0"/>
    <dynamics damping="0.1" friction="0.1"/>
  </joint>
  <joint name="l_wrist_pitch" type="revolute">
    <origin rpy="0 0 0" xyz="0 0 0"/>
    <parent link="l_wrist_dummy_link1"/>
    <child link="l_wrist_dummy_link2"/>
    <axis xyz="0 1 0"/>
    <limit effort="1000.0" lower="-0.7853981633974483" upper="0.7853981633974483" velocity="100.0"/>
    <dynamics damping="0.1" friction="0.1"/>
  </joint>
  <joint name="l_wrist_yaw" type="revolute">
    <origin rpy="0 0 0" xyz="0 0 0"/>
    <parent link="l_wrist_dummy_link2"/>
    <child link="l_wrist_link"/>
    <axis xyz="0 0 1"/>
    <limit effort="1000.0" lower="-1.57" upper="1.57" velocity="100.0"/>
    <dynamics damping="0.1" friction="0.1"/>
  </joint>
  <!-- URDF definition is so stupid we have to do that... -->
  <!-- <material name="gripperblack"> -->
  <!--     <color rgba="0.4 0.4 0.4 1"/> -->
  <!-- </material> -->
  <!-- <material name="gripperwhite"> -->
  <!--     <color rgba="0.9 0.9 0.9 1"/> -->
  <!-- </material> -->
  <!-- <material name="reachy_yellow"> -->
  <!--     <color rgba="0.8 0.8 0.0 1"/> -->
  <!-- </material> -->
  <!-- <material name="reachy_grey"> -->
  <!--     <color rgba="0.8 0.8 0.8 1"/> -->
  <!-- </material> -->
  <!-- <material name="reachy_metal"> -->
  <!--     <color rgba="0.85 0.85 0.85 1.0"/> -->
  <!-- </material> -->
  <!-- <material name="torsoblack"> -->
  <!--     <color rgba="0.5 0.5 0.5 1.0"/> -->
  <!-- </material> -->
  <!-- <material name="eyewhite"> -->
  <!--     <color rgba="1.0 1.0 1.0 1.0"/> -->
  <!-- </material> -->
  <!-- <material name="orbita2dmetal"> -->
  <!--     <color rgba="0.85 0.85 0.85 1.0"/> -->
  <!-- </material> -->
  <!-- <material name="orbita2dgrey"> -->
  <!--     <color rgba="0.8 0.8 0.8 1.0"/> -->
  <!-- </material> -->
  <!-- <material name="orbita3d_yellow"> -->
  <!--     <color rgba="0.8 0.8 0.0 1"/> -->
  <!-- </material> -->
  <!-- <material name="orbita3d_grey"> -->
  <!--     <color rgba="0.8 0.8 0.8 1"/> -->
  <!-- </material> -->
  <!-- <material name="gripperblack"> -->
  <!--     <color rgba="0.4 0.4 0.4 1"/> -->
  <!-- </material> -->
  <!-- <material name="gripperwhite"> -->
  <!--     <color rgba="0.9 0.9 0.9 1"/> -->
  <!-- </material> -->
  <link name="l_hand_palm_link">
    <collision>
      <!-- <origin xyz="0 0 0.04 " rpy="0 0 0"/> -->
      <origin rpy="0 0 0" xyz="0 0 0.0 "/>
      <geometry>
        <!-- <box size="${gripper_radius} ${gripper_radius*2} ${gripper_length/2}"/> -->
        <!-- <box size="0.08 0.12 0.07"/> -->
        <!-- <mesh filename="file://$(find arm_description)/meshes/pincette_left_collider.dae" /> -->
        <mesh filename="file:///home/reachy/reachy_ws/install/arm_description/share/arm_description/meshes/pincette_left_collider.dae"/>
      </geometry>
    </collision>
    <visual>
      <origin rpy="0 0 0" xyz="0 0 0"/>
      <geometry>
        <!-- <mesh filename="file://$(find arm_description)/meshes/pincette_left_visual.dae" /> -->
        <mesh filename="file:///home/reachy/reachy_ws/install/arm_description/share/arm_description/meshes/pincette_left_visual.dae"/>
      </geometry>
    </visual>
    <inertial>
      <origin rpy="0 0 0" xyz="0.00883565 -0.00950712 0.0451131"/>
      <mass value="0.30798029"/>
      <inertia ixx="0.00021804" ixy="0.00003011" ixz="-0.00001678" iyx="0.00003011" iyy="0.00016751" iyz="0.00001336" izx="-0.00001678" izy="0.00001336" izz="0.00023333"/>
    </inertial>
  </link>
  <joint name="l_hand_palm" type="fixed">
    <origin rpy="0.0 0 0" xyz="0 0 0"/>
    <parent link="l_wrist_out_link"/>
    <child link="l_hand_palm_link"/>
  </joint>
  <link name="l_hand_virtual_gripper_link">
    <inertial>
      <origin rpy="0.0 0.0 0.0" xyz="0.0 0.0 0.0"/>
      <mass value="0.001"/>
      <inertia ixx="1.0e-6" ixy="1.0e-8" ixz="1.0e-8" iyy="1.0e-6" iyz="1.0e-8" izz="1.0e-6"/>
    </inertial>
  </link>
  <joint name="l_hand_finger" type="revolute">
    <origin rpy="0 0 0" xyz="0.0 0.0 0.070028"/>
    <parent link="l_hand_palm_link"/>
    <child link="l_hand_virtual_gripper_link"/>
    <axis xyz="1 0 0"/>
    <limit effort="100.0" lower="0.0" upper="2.27" velocity="10.0"/>
    <dynamics damping="0.1" friction="0.1"/>
  </joint>
  <link name="l_hand_proximal_link">
    <inertial>
      <origin rpy="0 0 0" xyz="0.00004101 0.002756 0.019654"/>
      <mass value="0.03926395"/>
      <inertia ixx="0.00001937" ixy="0.0" ixz="7e-8" iyx="0.0" iyy="0.00002003" iyz="3.6e-7" izx="7e-8" izy="3.6e-7" izz="0.00000463"/>
    </inertial>
    <collision>
      <!-- <origin xyz="0 0.006 0.03 " rpy="0 0 0"/> -->
      <!-- <geometry> -->
      <!--   <box size="0.031 0.026 0.06"/> -->
      <!-- </geometry> -->
      <origin rpy="0 0 0" xyz="0 0.00 0.0 "/>
      <geometry>
        <!-- <mesh filename="file://$(find arm_description)/meshes/pincette_proximal_collider.dae" /> -->
        <mesh filename="file:///home/reachy/reachy_ws/install/arm_description/share/arm_description/meshes/pincette_proximal_collider.dae"/>
      </geometry>
    </collision>
    <visual>
      <origin rpy="0 0 0" xyz="0 0 0 "/>
      <geometry>
        <!-- <mesh filename="file://$(find arm_description)/meshes/pincette_proximal_visual.dae" /> -->
        <mesh filename="file:///home/reachy/reachy_ws/install/arm_description/share/arm_description/meshes/pincette_proximal_visual.dae"/>
      </geometry>
    </visual>
  </link>
  <link name="l_hand_proximal_mimic_link">
    <inertial>
      <origin rpy="0 0 0" xyz="0.00004101 0.002756 0.019654"/>
      <mass value="0.03926395"/>
      <inertia ixx="0.00001937" ixy="0.0" ixz="7e-8" iyx="0.0" iyy="0.00002003" iyz="3.6e-7" izx="7e-8" izy="3.6e-7" izz="0.00000463"/>
    </inertial>
    <collision>
      <!-- <origin xyz="0 0.006 0.03 " rpy="0 0 0"/> -->
      <origin rpy="0 0 0" xyz="0 0.0 0.0 "/>
      <geometry>
        <!-- <box size="0.031 0.026 0.06"/> -->
        <!-- <mesh filename="file://$(find arm_description)/meshes/pincette_proximal_collider.dae" /> -->
        <mesh filename="file:///home/reachy/reachy_ws/install/arm_description/share/arm_description/meshes/pincette_proximal_collider.dae"/>
      </geometry>
    </collision>
    <visual>
      <origin rpy="0 0 0" xyz="0 0 0 "/>
      <geometry>
        <!-- <mesh filename="file://$(find arm_description)/meshes/pincette_proximal_visual.dae" /> -->
        <mesh filename="file:///home/reachy/reachy_ws/install/arm_description/share/arm_description/meshes/pincette_proximal_visual.dae"/>
      </geometry>
    </visual>
  </link>
  <joint name="l_hand_finger_proximal" type="revolute">
    <origin rpy="0 0 0" xyz="-0.010196 0.03792 0.070028"/>
    <parent link="l_hand_palm_link"/>
    <child link="l_hand_proximal_link"/>
    <axis xyz="1 0 0"/>
    <limit effort="100.0" lower="-0.51" upper="0.554" velocity="10.0"/>
    <mimic joint="l_hand_finger" multiplier="-0.4689" offset="0.554"/>
    <dynamics damping="0.1" friction="0.1"/>
  </joint>
  <joint name="l_hand_finger_proximal_mimic" type="revolute">
    <origin rpy="0 0 3.141592" xyz="-0.010196 -0.03792 0.070028"/>
    <parent link="l_hand_palm_link"/>
    <child link="l_hand_proximal_mimic_link"/>
    <axis xyz="1 0 0"/>
    <limit effort="100.0" lower="-0.51" upper="0.554" velocity="10.0"/>
    <dynamics damping="0.1" friction="0.1"/>
    <mimic joint="l_hand_finger_proximal" multiplier="1" offset="0"/>
    <dynamics damping="0.1" friction="0.1"/>
  </joint>
  <link name="l_hand_distal_link">
    <inertial>
      <origin rpy="0 0 0" xyz="0.00000695 -0.00006402 0.01772685"/>
      <mass value="0.02821091"/>
      <inertia ixx="0.00000683" ixy="0.0" ixz="0.0" iyx="0.0" iyy="0.00000696" iyz="0.00000127" izx="0.0" izy="0.00000127" izz="0.0000028"/>
    </inertial>
    <collision>
      <!-- <origin xyz="0 0.0015 0.023 " rpy="0 0 0"/> -->
      <origin rpy="0 0 0" xyz="0 0.0 0.0 "/>
      <geometry>
        <!-- <box size="0.031 0.026 0.046"/> -->
        <!-- <mesh filename="file://$(find arm_description)/meshes/pincette_distal_collider.dae" /> -->
        <mesh filename="file:///home/reachy/reachy_ws/install/arm_description/share/arm_description/meshes/pincette_distal_collider.dae"/>
      </geometry>
    </collision>
    <visual>
      <origin rpy="0 0 0" xyz="0 0 0 "/>
      <geometry>
        <!-- <mesh filename="file://$(find arm_description)/meshes/pincette_distal.dae" /> -->
        <mesh filename="file:///home/reachy/reachy_ws/install/arm_description/share/arm_description/meshes/pincette_distal.dae"/>
      </geometry>
    </visual>
  </link>
  <joint name="l_hand_finger_distal" type="revolute">
    <origin rpy="0 0 0" xyz="0 0 0.049997"/>
    <parent link="l_hand_proximal_link"/>
    <child link="l_hand_distal_link"/>
    <axis xyz="1 0 0"/>
    <limit effort="100.0" lower="-0.51" upper="0.554" velocity="10.0"/>
    <!-- <mimic joint="${p}_finger_proximal" multiplier="-1" offset="0" /> -->
    <mimic joint="l_hand_finger" multiplier="0.4689" offset="-0.554"/>
    <dynamics damping="0.1" friction="0.1"/>
  </joint>
  <link name="l_hand_distal_mimic_link">
    <inertial>
      <origin rpy="0 0 0" xyz="0.00000695 -0.00006402 0.01772685"/>
      <mass value="0.02821091"/>
      <inertia ixx="0.00000683" ixy="0.0" ixz="0.0" iyx="0.0" iyy="0.00000696" iyz="0.00000127" izx="0.0" izy="0.00000127" izz="0.0000028"/>
    </inertial>
    <collision>
      <!-- <origin xyz="0 0.0015 0.023 " rpy="0 0 0"/> -->
      <origin rpy="0 0 0" xyz="0 0.00 0.0 "/>
      <geometry>
        <!-- <box size="0.031 0.026 0.046"/> -->
        <!-- <mesh filename="file://$(find arm_description)/meshes/pincette_distal_collider.dae" /> -->
        <mesh filename="file:///home/reachy/reachy_ws/install/arm_description/share/arm_description/meshes/pincette_distal_collider.dae"/>
      </geometry>
    </collision>
    <visual>
      <origin rpy="0 0 0" xyz="0 0 0 "/>
      <geometry>
        <!-- <mesh filename="file://$(find arm_description)/meshes/pincette_distal.dae" /> -->
        <mesh filename="file:///home/reachy/reachy_ws/install/arm_description/share/arm_description/meshes/pincette_distal.dae"/>
      </geometry>
    </visual>
  </link>
  <joint name="l_hand_finger_distal_mimic" type="revolute">
    <origin rpy="0 0 0" xyz="0 0 0.049997"/>
    <parent link="l_hand_proximal_mimic_link"/>
    <child link="l_hand_distal_mimic_link"/>
    <axis xyz="1 0 0"/>
    <limit effort="100.0" lower="-0.51" upper="0.554" velocity="10.0"/>
    <!-- <mimic joint="${p}_finger_proximal" multiplier="-1" offset="0" /> -->
    <mimic joint="l_hand_finger" multiplier="0.4689" offset="-0.554"/>
    <dynamics damping="0.1" friction="0.1"/>
  </joint>
  <link name="l_arm_tip">
    <inertial>
      <origin rpy="0.0 0.0 0.0" xyz="0.0 0.0 0.0"/>
      <mass value="0.001"/>
      <inertia ixx="1.0e-6" ixy="1.0e-8" ixz="1.0e-8" iyy="1.0e-6" iyz="1.0e-8" izz="1.0e-6"/>
    </inertial>
  </link>
  <joint name="l_tip_joint" type="fixed">
    <origin rpy="3.141592653589793 0 0" xyz="0 0 0.1"/>
    <parent link="l_hand_palm_link"/>
    <child link="l_arm_tip"/>
  </joint>
  <ros2_control name="l_arm" type="system">
    <hardware>
      <!-- ROS2 generic fake system -->
      <!-- <plugin>fake_components/GenericSystem</plugin> -->
      <!-- Pollen controllers fake system (simulate a little more) -->
      <plugin>arm_system_hwi/ArmSystemHwi</plugin>
      <param name="config_file">/home/reachy/reachy_ws/install/arm_description/share/arm_description/config/fake_arm.yaml</param>
    </hardware>
    <gpio name="l_shoulder">
      <state_interface name="torque">
        <param name="initial_value">0.0</param>
      </state_interface>
      <command_interface name="torque"/>
    </gpio>
    <joint name="l_shoulder_pitch">
      <state_interface name="position">
        <param name="initial_value">0.0</param>
      </state_interface>
      <state_interface name="velocity">
        <param name="initial_value">0.0</param>
      </state_interface>
      <state_interface name="effort">
        <param name="initial_value">0.0</param>
      </state_interface>
      <command_interface name="position"/>
    </joint>
    <joint name="l_shoulder_roll">
      <state_interface name="position">
        <param name="initial_value">0.0</param>
      </state_interface>
      <state_interface name="velocity">
        <param name="initial_value">0.0</param>
      </state_interface>
      <state_interface name="effort">
        <param name="initial_value">0.0</param>
      </state_interface>
      <command_interface name="position"/>
    </joint>
    <gpio name="l_shoulder_raw_motor_1">
      <state_interface name="speed_limit"/>
      <command_interface name="speed_limit"/>
      <state_interface name="torque_limit"/>
      <command_interface name="torque_limit"/>
      <state_interface name="p_gain"/>
      <command_interface name="p_gain"/>
      <state_interface name="i_gain"/>
      <command_interface name="i_gain"/>
      <state_interface name="d_gain"/>
      <command_interface name="d_gain"/>
    </gpio>
    <gpio name="l_shoulder_raw_motor_2">
      <state_interface name="speed_limit"/>
      <command_interface name="speed_limit"/>
      <state_interface name="torque_limit"/>
      <command_interface name="torque_limit"/>
      <state_interface name="p_gain"/>
      <command_interface name="p_gain"/>
      <state_interface name="i_gain"/>
      <command_interface name="i_gain"/>
      <state_interface name="d_gain"/>
      <command_interface name="d_gain"/>
    </gpio>
    <gpio name="l_elbow">
      <state_interface name="torque">
        <param name="initial_value">0.0</param>
      </state_interface>
      <command_interface name="torque"/>
    </gpio>
    <joint name="l_elbow_yaw">
      <state_interface name="position">
        <param name="initial_value">0.0</param>
      </state_interface>
      <state_interface name="velocity">
        <param name="initial_value">0.0</param>
      </state_interface>
      <state_interface name="effort">
        <param name="initial_value">0.0</param>
      </state_interface>
      <command_interface name="position"/>
    </joint>
    <joint name="l_elbow_pitch">
      <state_interface name="position">
        <param name="initial_value">0.0</param>
      </state_interface>
      <state_interface name="velocity">
        <param name="initial_value">0.0</param>
      </state_interface>
      <state_interface name="effort">
        <param name="initial_value">0.0</param>
      </state_interface>
      <command_interface name="position"/>
    </joint>
    <gpio name="l_elbow_raw_motor_1">
      <state_interface name="speed_limit"/>
      <command_interface name="speed_limit"/>
      <state_interface name="torque_limit"/>
      <command_interface name="torque_limit"/>
      <state_interface name="p_gain"/>
      <command_interface name="p_gain"/>
      <state_interface name="i_gain"/>
      <command_interface name="i_gain"/>
      <state_interface name="d_gain"/>
      <command_interface name="d_gain"/>
    </gpio>
    <gpio name="l_elbow_raw_motor_2">
      <state_interface name="speed_limit"/>
      <command_interface name="speed_limit"/>
      <state_interface name="torque_limit"/>
      <command_interface name="torque_limit"/>
      <state_interface name="p_gain"/>
      <command_interface name="p_gain"/>
      <state_interface name="i_gain"/>
      <command_interface name="i_gain"/>
      <state_interface name="d_gain"/>
      <command_interface name="d_gain"/>
    </gpio>
    <gpio name="l_wrist">
      <state_interface name="torque">
        <param name="initial_value">0.0</param>
      </state_interface>
      <command_interface name="torque"/>
    </gpio>
    <joint name="l_wrist_roll">
      <state_interface name="position">
        <param name="initial_value">0.0</param>
      </state_interface>
      <state_interface name="velocity">
        <param name="initial_value">0.0</param>
      </state_interface>
      <state_interface name="effort">
        <param name="initial_value">0.0</param>
      </state_interface>
      <command_interface name="position"/>
    </joint>
    <joint name="l_wrist_pitch">
      <state_interface name="position">
        <param name="initial_value">0.0</param>
      </state_interface>
      <state_interface name="velocity">
        <param name="initial_value">0.0</param>
      </state_interface>
      <state_interface name="effort">
        <param name="initial_value">0.0</param>
      </state_interface>
      <command_interface name="position"/>
    </joint>
    <joint name="l_wrist_yaw">
      <state_interface name="position">
        <param name="initial_value">0.0</param>
      </state_interface>
      <state_interface name="velocity">
        <param name="initial_value">0.0</param>
      </state_interface>
      <state_interface name="effort">
        <param name="initial_value">0.0</param>
      </state_interface>
      <command_interface name="position"/>
    </joint>
    <gpio name="l_wrist_raw_motor_1">
      <state_interface name="speed_limit"/>
      <command_interface name="speed_limit"/>
      <state_interface name="torque_limit"/>
      <command_interface name="torque_limit"/>
      <state_interface name="p_gain"/>
      <command_interface name="p_gain"/>
      <state_interface name="i_gain"/>
      <command_interface name="i_gain"/>
      <state_interface name="d_gain"/>
      <command_interface name="d_gain"/>
    </gpio>
    <gpio name="l_wrist_raw_motor_2">
      <state_interface name="speed_limit"/>
      <command_interface name="speed_limit"/>
      <state_interface name="torque_limit"/>
      <command_interface name="torque_limit"/>
      <state_interface name="p_gain"/>
      <command_interface name="p_gain"/>
      <state_interface name="i_gain"/>
      <command_interface name="i_gain"/>
      <state_interface name="d_gain"/>
      <command_interface name="d_gain"/>
    </gpio>
    <gpio name="l_wrist_raw_motor_3">
      <state_interface name="speed_limit"/>
      <command_interface name="speed_limit"/>
      <state_interface name="torque_limit"/>
      <command_interface name="torque_limit"/>
      <state_interface name="p_gain"/>
      <command_interface name="p_gain"/>
      <state_interface name="i_gain"/>
      <command_interface name="i_gain"/>
      <state_interface name="d_gain"/>
      <command_interface name="d_gain"/>
    </gpio>
    <gpio name="l_hand">
      <state_interface name="torque">
        <param name="initial_value">0.0</param>
      </state_interface>
      <command_interface name="torque"/>
    </gpio>
    <joint name="l_hand_finger">
      <state_interface name="position">
        <param name="initial_value">0.0</param>
      </state_interface>
      <state_interface name="velocity">
        <param name="initial_value">0.0</param>
      </state_interface>
      <state_interface name="effort">
        <param name="initial_value">0.0</param>
      </state_interface>
      <command_interface name="position"/>
    </joint>
    <gpio name="l_hand_raw_motor_1">
      <state_interface name="speed_limit"/>
      <command_interface name="speed_limit"/>
      <state_interface name="torque_limit"/>
      <command_interface name="torque_limit"/>
      <state_interface name="p_gain"/>
      <command_interface name="p_gain"/>
      <state_interface name="i_gain"/>
      <command_interface name="i_gain"/>
      <state_interface name="d_gain"/>
      <command_interface name="d_gain"/>
    </gpio>
  </ros2_control>
  <link name="sr_cam_l_optical">
    <inertial>
      <origin rpy="0.0 0.0 0.0" xyz="0.0 0.0 0.0"/>
      <mass value="0.001"/>
      <inertia ixx="1.0e-6" ixy="1.0e-8" ixz="1.0e-8" iyy="1.0e-6" iyz="1.0e-8" izz="1.0e-6"/>
    </inertial>
  </link>
  <link name="sr_cam_l_frame">
    <inertial>
      <origin rpy="0.0 0.0 0.0" xyz="0.0 0.0 0.0"/>
      <mass value="0.001"/>
      <inertia ixx="1.0e-6" ixy="1.0e-8" ixz="1.0e-8" iyy="1.0e-6" iyz="1.0e-8" izz="1.0e-6"/>
    </inertial>
  </link>
  <joint name="sr_cam_l_optical_joint" type="fixed">
    <origin rpy="-2.4085543677521746 0.0 -1.5707963267948966" xyz="0.002597 0.009989 0.038089"/>
    <parent link="logo"/>
    <child link="sr_cam_l_optical"/>
  </joint>
  <joint name="sr_cam_l_frame_joint" type="fixed">
    <origin rpy="0.0 0.8377580409572782 0.0" xyz="0.002597 0.009989 0.038089"/>
    <parent link="logo"/>
    <child link="sr_cam_l_frame"/>
  </joint>
  <link name="sr_cam_r_optical">
    <inertial>
      <origin rpy="0.0 0.0 0.0" xyz="0.0 0.0 0.0"/>
      <mass value="0.001"/>
      <inertia ixx="1.0e-6" ixy="1.0e-8" ixz="1.0e-8" iyy="1.0e-6" iyz="1.0e-8" izz="1.0e-6"/>
    </inertial>
  </link>
  <link name="sr_cam_r_frame">
    <inertial>
      <origin rpy="0.0 0.0 0.0" xyz="0.0 0.0 0.0"/>
      <mass value="0.001"/>
      <inertia ixx="1.0e-6" ixy="1.0e-8" ixz="1.0e-8" iyy="1.0e-6" iyz="1.0e-8" izz="1.0e-6"/>
    </inertial>
  </link>
  <joint name="sr_cam_r_optical_joint" type="fixed">
    <origin rpy="-2.4085543677521746 0.0 -1.5707963267948966" xyz="0.002597 -0.009989 0.038089"/>
    <parent link="logo"/>
    <child link="sr_cam_r_optical"/>
  </joint>
  <joint name="sr_cam_r_frame_joint" type="fixed">
    <origin rpy="0.0 0.8377580409572782 0.0 " xyz="0.002597 -0.009989 0.038089"/>
    <parent link="logo"/>
    <child link="sr_cam_r_frame"/>
  </joint>
  <gazebo reference="sr_cam_l_frame">
    <!-- <link name="left_camera"> -->
    <sensor name="left_camera" type="camera">
      <!-- Set always_on only sensor, not on plugin -->
      <always_on>0</always_on>
      <!-- Set update_rate only sensor, not on plugin -->
      <update_rate>30</update_rate>
      <camera name="sr_cam_l">
        <horizontal_fov>1.3962634</horizontal_fov>
        <image>
          <width>800</width>
          <height>800</height>
          <format>R8G8B8</format>
        </image>
        <distortion>
          <k1>0.0</k1>
          <k2>0.0</k2>
          <k3>0.0</k3>
          <p1>0.0</p1>
          <p2>0.0</p2>
          <center>0.5 0.5</center>
        </distortion>
        <noise>
          <type>gaussian</type>
          <mean>0.0</mean>
          <stddev>0.007</stddev>
        </noise>
      </camera>
      <!-- Use camera, not camera_triggered -->
      <plugin filename="libgazebo_ros_camera.so" name="sr_left_camera_controller">
        <ros>
          <namespace>/</namespace>
          <remapping>image_raw:=image_raw</remapping>
          <remapping>camera_info:=camera_info</remapping>
        </ros>
        <camera_name>sr_left_image</camera_name>
        <!-- <ros> -->
        <!--   <namespace>custom_ns</namespace> -->
        <!--   <argument>image_raw:=custom_img</argument> -->
        <!--   <argument>camera_info:=custom_info</argument> -->
        <!-- </ros> -->
        <!-- Set camera name. If empty, defaults to sensor name (i.e. "sensor_name") -->
        <!-- <camera_name>left_camera</camera_name> -->
        <!-- Set TF frame name. If empty, defaults to link name (i.e. "link_name") -->
        <frame_name>sr_cam_l_optical</frame_name>
        <hack_baseline>0.07</hack_baseline>
        <!-- No need to repeat distortion parameters or to set autoDistortion -->
      </plugin>
    </sensor>
  </gazebo>
  <gazebo reference="sr_cam_r_frame">
    <!-- <link name="left_camera"> -->
    <sensor name="right_camera" type="camera">
      <!-- Set always_on only sensor, not on plugin -->
      <always_on>0</always_on>
      <!-- Set update_rate only sensor, not on plugin -->
      <update_rate>30</update_rate>
      <camera name="sr_cam_r">
        <horizontal_fov>1.3962634</horizontal_fov>
        <image>
          <width>800</width>
          <height>800</height>
          <format>R8G8B8</format>
        </image>
        <distortion>
          <k1>0.0</k1>
          <k2>0.0</k2>
          <k3>0.0</k3>
          <p1>0.0</p1>
          <p2>0.0</p2>
          <center>0.5 0.5</center>
        </distortion>
        <noise>
          <type>gaussian</type>
          <mean>0.0</mean>
          <stddev>0.007</stddev>
        </noise>
      </camera>
      <!-- Use camera, not camera_triggered -->
      <plugin filename="libgazebo_ros_camera.so" name="sr_right_camera_controller">
        <ros>
          <namespace>/</namespace>
          <remapping>image_raw:=image_raw</remapping>
          <remapping>camera_info:=camera_info</remapping>
        </ros>
        <camera_name>sr_right_image</camera_name>
        <!-- <ros> -->
        <!--   <namespace>custom_ns</namespace> -->
        <!--   <argument>image_raw:=custom_img</argument> -->
        <!--   <argument>camera_info:=custom_info</argument> -->
        <!-- </ros> -->
        <!-- Set camera name. If empty, defaults to sensor name (i.e. "sensor_name") -->
        <!-- <camera_name>left_camera</camera_name> -->
        <!-- Set TF frame name. If empty, defaults to link name (i.e. "link_name") -->
        <frame_name>sr_cam_r_optical</frame_name>
        <hack_baseline>0.07</hack_baseline>
        <!-- No need to repeat distortion parameters or to set autoDistortion -->
      </plugin>
    </sensor>
  </gazebo>
  <gazebo reference="sr_cam_l_frame">
    <sensor name="depth_camera" type="depth">
      <always_on>true</always_on>
      <update_rate>15</update_rate>
      <pose>0 0 0 0 0 0</pose>
      <camera name="realsense_depth_camera">
        <horizontal_fov>1.46608</horizontal_fov>
        <image>
          <width>424</width>
          <height>240</height>
          <format>B8G8R8</format>
        </image>
        <clip>
          <near>0.05</near>
          <far>8</far>
        </clip>
      </camera>
      <!-- https://github.com/mlherd/ros2_turtlebot3_waffle_intel_realsense -->
      <!-- <plugin name="intel_realsense_d430_depth_driver" filename="libgazebo_ros_camera.so"> -->
      <plugin filename="libgazebo_ros_camera.so" name="intel_realsense_r200_depth_driver">
        <ros>
          <namespace>depth_camera</namespace>
          <remapping>depth_camera/image_raw:=color/image_raw</remapping>
          <remapping>depth_camera/depth/image_raw:=depth/image_rect_raw</remapping>
          <remapping>depth_camera/camera_info:=camera_info</remapping>
          <remapping>depth_camera/depth/camera_info:=depth/camera_info</remapping>
          <remapping>depth_camera/points:=depth/points</remapping>
        </ros>
        <camera_name>depth_camera</camera_name>
        <frame_name>sr_cam_l_optical</frame_name>
        <hack_baseline>0.07</hack_baseline>
        <min_depth>0.05</min_depth>
        <max_depth>8.0</max_depth>
      </plugin>
    </sensor>
  </gazebo>
  <!-- <link name="r_wrist_cam_frame"/> -->
  <!-- <joint name="r_wrist_cam_frame_joint" type="fixed"> -->
  <!--   <origin xyz="0 0 0" rpy="0.0 0 0"/> -->
  <!--   <parent link="r_gripper_palm_link"/> -->
  <!--   <child link="r_wrist_cam_frame"/> -->
  <!-- </joint> -->
  <!-- <link name="r_wrist_camera"/> -->
  <!-- <joint name="r_wrist_camera_joint" type="fixed"> -->
  <!--   <origin xyz="0.11 -0.01 0.08" rpy="0.35 -0.7 0"/> -->
  <!--   <parent link="r_wrist_cam_frame"/> -->
  <!--   <child link="r_wrist_camera"/> -->
  <!-- </joint> -->
</robot>
